Workbook

Sheet 使用說明
A1: 童芯日間照顧｜2026（民國115年）薪資與保費管理表
A3: 使用順序 | B3: ①先到「員工設定」輸入10位員工姓名；②在健保、勞保、勞退分頁輸入每月公司實際繳費及員工明細；③在各員工個人分頁輸入薪資匯款日期、薪資金額與薪資明細。
A4: 黃色欄位 | B4: 需自行輸入資料。
A5: 綠色欄位 | B5: 公式連動欄位，請勿覆蓋。
A6: 員工姓名 | B6: 只需在「員工設定」更改姓名，保費明細及個人分頁會依員工代號連動，不必在每個分頁重複改名。
A7: 月份 | B7: 資料列已預先建立2026年1月至12月。每月每位員工一列；若同一員工同月有多筆資料，可在該月增加一列並複製公式/格式。
A8: 保費摘要 | B8: 公司實際支付總額、支付日期、明細狀況、收據狀況請依繳費資料填寫；摘要金額不會自動以員工分攤金額取代。
A9: 個人分頁 | B9: 薪資匯款日期、薪資金額、薪資明細由使用者輸入；六項保費/提繳金額會依月份及員工設定自動帶入。
A10: 重要提醒 | B10: 本表是帳務紀錄與連動工具，不會判斷或核定法定投保級距、實際應繳保費或勞退提繳率。請以官方繳款單、明細及薪資紀錄核對。

Sheet 員工設定
A1: 員工姓名設定（請先填寫此頁）
A3: 員工代號 | B3: 員工姓名 | C3: 備註
A4: E01 | B4: 員工01 | C4: 請將預設名稱改成實際姓名
A5: E02 | B5: 員工02 | C5: 請將預設名稱改成實際姓名
A6: E03 | B6: 員工03 | C6: 請將預設名稱改成實際姓名
A7: E04 | B7: 員工04 | C7: 請將預設名稱改成實際姓名
A8: E05 | B8: 員工05 | C8: 請將預設名稱改成實際姓名
A9: E06 | B9: 員工06 | C9: 請將預設名稱改成實際姓名
A10: E07 | B10: 員工07 | C10: 請將預設名稱改成實際姓名
A11: E08 | B11: 員工08 | C11: 請將預設名稱改成實際姓名
A12: E09 | B12: 員工09 | C12: 請將預設名稱改成實際姓名
A13: E10 | B13: 員工10 | C13: 請將預設名稱改成實際姓名
A16: 注意 | B16: 更改姓名後，其他分頁會自動連動；請勿刪除員工列或更改員工代號。

Sheet 健保
A1: 健保｜2026年度繳費摘要
A3: 月份 | B3: 公司實際支付健保費總額 | C3: 支付日期 | D3: 明細狀況 | E3: 收據狀況 | G3: 填寫提示
A4: 46023 | G4: 黃色欄位請自行輸入。摘要總額請依實際繳費單填寫。
A5: 46054
A6: 46082
A7: 46113
A8: 46143
A9: 46174
A10: 46204
A11: 46235
A12: 46266
A13: 46296
A14: 46327
A15: 46357
A18: 健保｜員工每月明細
A20: 月份 | B20: 員工名稱 | C20: 健保個人負擔 | D20: 健保公司負擔
A21: 46023 | B21: ='員工設定'!$B$4
A22: 46023 | B22: ='員工設定'!$B$5
A23: 46023 | B23: ='員工設定'!$B$6
A24: 46023 | B24: ='員工設定'!$B$7
A25: 46023 | B25: ='員工設定'!$B$8
A26: 46023 | B26: ='員工設定'!$B$9
A27: 46023 | B27: ='員工設定'!$B$10
A28: 46023 | B28: ='員工設定'!$B$11
A29: 46023 | B29: ='員工設定'!$B$12
A30: 46023 | B30: ='員工設定'!$B$13
A31: 46054 | B31: ='員工設定'!$B$4
A32: 46054 | B32: ='員工設定'!$B$5
A33: 46054 | B33: ='員工設定'!$B$6
A34: 46054 | B34: ='員工設定'!$B$7
A35: 46054 | B35: ='員工設定'!$B$8
A36: 46054 | B36: ='員工設定'!$B$9
A37: 46054 | B37: ='員工設定'!$B$10
A38: 46054 | B38: ='員工設定'!$B$11
A39: 46054 | B39: ='員工設定'!$B$12
A40: 46054 | B40: ='員工設定'!$B$13
A41: 46082 | B41: ='員工設定'!$B$4
A42: 46082 | B42: ='員工設定'!$B$5
A43: 46082 | B43: ='員工設定'!$B$6
A44: 46082 | B44: ='員工設定'!$B$7
...

Sheet 勞保
A1: 勞保｜2026年度繳費摘要
A3: 月份 | B3: 公司實際支付勞保費總額 | C3: 支付日期 | D3: 明細狀況 | E3: 收據狀況 | G3: 填寫提示
A4: 46023 | G4: 黃色欄位請自行輸入。摘要總額請依實際繳費單填寫。
A5: 46054
A6: 46082
A7: 46113
A8: 46143
A9: 46174
A10: 46204
A11: 46235
A12: 46266
A13: 46296
A14: 46327
A15: 46357
A18: 勞保｜員工每月明細
A20: 月份 | B20: 員工名稱 | C20: 勞保個人負擔 | D20: 勞保公司負擔
A21: 46023 | B21: ='員工設定'!$B$4
A22: 46023 | B22: ='員工設定'!$B$5
A23: 46023 | B23: ='員工設定'!$B$6
A24: 46023 | B24: ='員工設定'!$B$7
A25: 46023 | B25: ='員工設定'!$B$8
A26: 46023 | B26: ='員工設定'!$B$9
A27: 46023 | B27: ='員工設定'!$B$10
A28: 46023 | B28: ='員工設定'!$B$11
A29: 46023 | B29: ='員工設定'!$B$12
A30: 46023 | B30: ='員工設定'!$B$13
A31: 46054 | B31: ='員工設定'!$B$4
A32: 46054 | B32: ='員工設定'!$B$5
A33: 46054 | B33: ='員工設定'!$B$6
A34: 46054 | B34: ='員工設定'!$B$7
A35: 46054 | B35: ='員工設定'!$B$8
A36: 46054 | B36: ='員工設定'!$B$9
A37: 46054 | B37: ='員工設定'!$B$10
A38: 46054 | B38: ='員工設定'!$B$11
A39: 46054 | B39: ='員工設定'!$B$12
A40: 46054 | B40: ='員工設定'!$B$13
A41: 46082 | B41: ='員工設定'!$B$4
A42: 46082 | B42: ='員工設定'!$B$5
A43: 46082 | B43: ='員工設定'!$B$6
A44: 46082 | B44: ='員工設定'!$B$7
...

Sheet 勞退
A1: 勞退｜2026年度繳費摘要
A3: 月份 | B3: 公司實際支付勞退費總額 | C3: 支付日期 | D3: 明細狀況 | E3: 收據狀況 | G3: 填寫提示
A4: 46023 | G4: 黃色欄位請自行輸入。摘要總額請依實際繳費單填寫。
A5: 46054
A6: 46082
A7: 46113
A8: 46143
A9: 46174
A10: 46204
A11: 46235
A12: 46266
A13: 46296
A14: 46327
A15: 46357
A18: 勞退｜員工每月明細
A20: 月份 | B20: 員工名稱 | C20: 勞退雇主提繳 | D20: 勞退個人自願提繳
A21: 46023 | B21: ='員工設定'!$B$4
A22: 46023 | B22: ='員工設定'!$B$5
A23: 46023 | B23: ='員工設定'!$B$6
A24: 46023 | B24: ='員工設定'!$B$7
A25: 46023 | B25: ='員工設定'!$B$8
A26: 46023 | B26: ='員工設定'!$B$9
A27: 46023 | B27: ='員工設定'!$B$10
A28: 46023 | B28: ='員工設定'!$B$11
A29: 46023 | B29: ='員工設定'!$B$12
A30: 46023 | B30: ='員工設定'!$B$13
A31: 46054 | B31: ='員工設定'!$B$4
A32: 46054 | B32: ='員工設定'!$B$5
A33: 46054 | B33: ='員工設定'!$B$6
A34: 46054 | B34: ='員工設定'!$B$7
A35: 46054 | B35: ='員工設定'!$B$8
A36: 46054 | B36: ='員工設定'!$B$9
A37: 46054 | B37: ='員工設定'!$B$10
A38: 46054 | B38: ='員工設定'!$B$11
A39: 46054 | B39: ='員工設定'!$B$12
A40: 46054 | B40: ='員工設定'!$B$13
A41: 46082 | B41: ='員工設定'!$B$4
A42: 46082 | B42: ='員工設定'!$B$5
A43: 46082 | B43: ='員工設定'!$B$6
A44: 46082 | B44: ='員工設定'!$B$7
...

Sheet 員工01
A1: 員工個人薪資與保費紀錄
A2: 員工姓名 | B2: ='員工設定'!B4 | D2: 員工代號 | E2: ='員工設定'!A4
A4: 月份 | B4: 薪資匯款日期 | C4: 薪資金額 | D4: 薪資明細 | E4: 健保公司負擔 | F4: 勞保公司負擔 | G4: 勞退雇主提繳 | H4: 健保個人負擔 | I4: 勞保個人負擔 | J4: 勞退個人自願提繳
A5: 46023 | E5: =SUMIFS(健保!$D$21:$D$140,健保!$A$21:$A$140,$A5,健保!$B$21:$B$140,$B$2) | F5: =SUMIFS(勞保!$D$21:$D$140,勞保!$A$21:$A$140,$A5,勞保!$B$21:$B$140,$B$2) | G5: =SUMIFS(勞退!$C$21:$C$140,勞退!$A$21:$A$140,$A5,勞退!$B$21:$B$140,$B$2) | H5: =SUMIFS(健保!$C$21:$C$140,健保!$A$21:$A$140,$A5,健保!$B$21:$B$140,$B$2) | I5: =SUMIFS(勞保!$C$21:$C$140,勞保!$A$21:$A$140,$A5,勞保!$B$21:$B$140,$B$2) | J5: =SUMIFS(勞退!$D$21:$D$140,勞退!$A$21:$A$140,$A5,勞退!$B$21:$B$140,$B$2)
A6: 46054 | E6: =SUMIFS(健保!$D$21:$D$140,健保!$A$21:$A$140,$A6,健保!$B$21:$B$140,$B$2) | F6: =SUMIFS(勞保!$D$21:$D$140,勞保!$A$21:$A$140,$A6,勞保!$B$21:$B$140,$B$2) | G6: =SUMIFS(勞退!$C$21:$C$140,勞退!$A$21:$A$140,$A6,勞退!$B$21:$B$140,$B$2) | H6: =SUMIFS(健保!$C$21:$C$140,健保!$A$21:$A$140,$A6,健保!$B$21:$B$140,$B$2) | I6: =SUMIFS(勞保!$C$21:$C$140,勞保!$A$21:$A$140,$A6,勞保!$B$21:$B$140,$B$2) | J6: =SUMIFS(勞退!$D$21:$D$140,勞退!$A$21:$A$140,$A6,勞退!$B$21:$B$140,$B$2)
A7: 46082 | E7: =SUMIFS(健保!$D$21:$D$140,健保!$A$21:$A$140,$A7,健保!$B$21:$B$140,$B$2) | F7: =SUMIFS(勞保!$D$21:$D$140,勞保!$A$21:$A$140,$A7,勞保!$B$21:$B$140,$B$2) | G7: =SUMIFS(勞退!$C$21:$C$140,勞退!$A$21:$A$140,$A7,勞退!$B$21:$B$140,$B$2) | H7: =SUMIFS(健保!$C$21:$C$140,健保!$A$21:$A$140,$A7,健保!$B$21:$B$140,$B$2) | I7: =SUMIFS(勞保!$C$21:$C$140,勞保!$A$21:$A$140,$A7,勞保!$B$21:$B$140,$B$2) | J7: =SUMIFS(勞退!$D$21:$D$140,勞退!$A$21:$A$140,$A7,勞退!$B$21:$B$140,$B$2)
A8: 46113 | E8: =SUMIFS(健保!$D$21:$D$140,健保!$A$21:$A$140,$A8,健保!$B$21:$B$140,$B$2) | F8: =SUMIFS(勞保!$D$21:$D$140,勞保!$A$21:$A$140,$A8,勞保!$B$21:$B$140,$B$2) | G8: =SUMIFS(勞退!$C$21:$C$140,勞退!$A$21:$A$140,$A8,勞退!$B$21:$B$140,$B$2) | H8: =SUMIFS(健保!$C$21:$C$140,健保!$A$21:$A$140,$A8,健保!$B$21:$B$140,$B$2) | I8: =SUMIFS(勞保!$C$21:$C$140,勞保!$A$21:$A$140,$A8,勞保!$B$21:$B$140,$B$2) | J8: =SUMIFS(勞退!$D$21:$D$140,勞退!$A$21:$A$140,$A8,勞退!$B$21:$B$140,$B$2)
A9: 46143 | E9: =SUMIFS(健保!$D$21:$D$140,健保!$A$21:$A$140,$A9,健保!$B$21:$B$140,$B$2) | F9: =SUMIFS(勞保!$D$21:$D$140,勞保!$A$21:$A$140,$A9,勞保!$B$21:$B$140,$B$2) | G9: =SUMIFS(勞退!$C$21:$C$140,勞退!$A$21:$A$140,$A9,勞退!$B$21:$B$140,$B$2) | H9: =SUMIFS(健保!$C$21:$C$140,健保!$A$21:$A$140,$A9,健保!$B$21:$B$140,$B$2) | I9: =SUMIFS(勞保!$C$21:$C$140,勞保!$A$21:$A$140,$A9,勞保!$B$21:$B$140,$B$2) | J9: =SUMIFS(勞退!$D$21:$D$140,勞退!$A$21:$A$140,$A9,勞退!$B$21:$B$140,$B$2)
A10: 46174 | E10: =SUMIFS(健保!$D$21:$D$140,健保!$A$21:$A$140,$A10,健保!$B$21:$B$140,$B$2) | F10: =SUMIFS(勞保!$D$21:$D$140,勞保!$A$21:$A$140,$A10,勞保!$B$21:$B$140,$B$2) | G10: =SUMIFS(勞退!$C$21:$C$140,勞退!$A$21:$A$140,$A10,勞退!$B$21:$B$140,$B$2) | H10: =SUMIFS(健保!$C$21:$C$140,健保!$A$21:$A$140,$A10,健保!$B$21:$B$140,$B$2) | I10: =SUMIFS(勞保!$C$21:$C$140,勞保!$A$21:$A$140,$A10,勞保!$B$21:$B$140,$B$2) | J10: =SUMIFS(勞退!$D$21:$D$140,勞退!$A$21:$A$140,$A10,勞退!$B$21:$B$140,$B$2)
A11: 46204 | E11: =SUMIFS(健保!$D$21:$D$140,健保!$A$21:$A$140,$A11,健保!$B$21:$B$140,$B$2) | F11: =SUMIFS(勞保!$D$21:$D$140,勞保!$A$21:$A$140,$A11,勞保!$B$21:$B$140,$B$2) | G11: =SUMIFS(勞退!$C$21:$C$140,勞退!$A$21:$A$140,$A11,勞退!$B$21:$B$140,$B$2) | H11: =SUMIFS(健保!$C$21:$C$140,健保!$A$21:$A$140,$A11,健保!$B$21:$B$140,$B$2) | I11: =SUMIFS(勞保!$C$21:$C$140,勞保!$A$21:$A$140,$A11,勞保!$B$21:$B$140,$B$2) | J11: =SUMIFS(勞退!$D$21:$D$140,勞退!$A$21:$A$140,$A11,勞退!$B$21:$B$140,$B$2)
A12: 46235 | E12: =SUMIFS(健保!$D$21:$D$140,健保!$A$21:$A$140,$A12,健保!$B$21:$B$140,$B$2) | F12: =SUMIFS(勞保!$D$21:$D$140,勞保!$A$21:$A$140,$A12,勞保!$B$21:$B$140,$B$2) | G12: =SUMIFS(勞退!$C$21:$C$140,勞退!$A$21:$A$140,$A12,勞退!$B$21:$B$140,$B$2) | H12: =SUMIFS(健保!$C$21:$C$140,健保!$A$21:$A$140,$A12,健保!$B$21:$B$140,$B$2) | I12: =SUMIFS(勞保!$C$21:$C$140,勞保!$A$21:$A$140,$A12,勞保!$B$21:$B$140,$B$2) | J12: =SUMIFS(勞退!$D$21:$D$140,勞退!$A$21:$A$140,$A12,勞退!$B$21:$B$140,$B$2)
A13: 46266 | E13: =SUMIFS(健保!$D$21:$D$140,健保!$A$21:$A$140,$A13,健保!$B$21:$B$140,$B$2) | F13: =SUMIFS(勞保!$D$21:$D$140,勞保!$A$21:$A$140,$A13,勞保!$B$21:$B$140,$B$2) | G13: =SUMIFS(勞退!$C$21:$C$140,勞退!$A$21:$A$140,$A13,勞退!$B$21:$B$140,$B$2) | H13: =SUMIFS(健保!$C$21:$C$140,健保!$A$21:$A$140,$A13,健保!$B$21:$B$140,$B$2) | I13: =SUMIFS(勞保!$C$21:$C$140,勞保!$A$21:$A$140,$A13,勞保!$B$21:$B$140,$B$2) | J13: =SUMIFS(勞退!$D$21:$D$140,勞退!$A$21:$A$140,$A13,勞退!$B$21:$B$140,$B$2)
A14: 46296 | E14: =SUMIFS(健保!$D$21:$D$140,健保!$A$21:$A$140,$A14,健保!$B$21:$B$140,$B$2) | F14: =SUMIFS(勞保!$D$21:$D$140,勞保!$A$21:$A$140,$A14,勞保!$B$21:$B$140,$B$2) | G14: =SUMIFS(勞退!$C$21:$C$140,勞退!$A$21:$A$140,$A14,勞退!$B$21:$B$140,$B$2) | H14: =SUMIFS(健保!$C$21:$C$140,健保!$A$21:$A$140,$A14,健保!$B$21:$B$140,$B$2) | I14: =SUMIFS(勞保!$C$21:$C$140,勞保!$A$21:$A$140,$A14,勞保!$B$21:$B$140,$B$2) | J14: =SUMIFS(勞退!$D$21:$D$140,勞退!$A$21:$A$140,$A14,勞退!$B$21:$B$140,$B$2)
A15: 46327 | E15: =SUMIFS(健保!$D$21:$D$140,健保!$A$21:$A$140,$A15,健保!$B$21:$B$140,$B$2) | F15: =SUMIFS(勞保!$D$21:$D$140,勞保!$A$21:$A$140,$A15,勞保!$B$21:$B$140,$B$2) | G15: =SUMIFS(勞退!$C$21:$C$140,勞退!$A$21:$A$140,$A15,勞退!$B$21:$B$140,$B$2) | H15: =SUMIFS(健保!$C$21:$C$140,健保!$A$21:$A$140,$A15,健保!$B$21:$B$140,$B$2) | I15: =SUMIFS(勞保!$C$21:$C$140,勞保!$A$21:$A$140,$A15,勞保!$B$21:$B$140,$B$2) | J15: =SUMIFS(勞退!$D$21:$D$140,勞退!$A$21:$A$140,$A15,勞退!$B$21:$B$140,$B$2)
A16: 46357 | E16: =SUMIFS(健保!$D$21:$D$140,健保!$A$21:$A$140,$A16,健保!$B$21:$B$140,$B$2) | F16: =SUMIFS(勞保!$D$21:$D$140,勞保!$A$21:$A$140,$A16,勞保!$B$21:$B$140,$B$2) | G16: =SUMIFS(勞退!$C$21:$C$140,勞退!$A$21:$A$140,$A16,勞退!$B$21:$B$140,$B$2) | H16: =SUMIFS(健保!$C$21:$C$140,健保!$A$21:$A$140,$A16,健保!$B$21:$B$140,$B$2) | I16: =SUMIFS(勞保!$C$21:$C$140,勞保!$A$21:$A$140,$A16,勞保!$B$21:$B$140,$B$2) | J16: =SUMIFS(勞退!$D$21:$D$140,勞退!$A$21:$A$140,$A16,勞退!$B$21:$B$140,$B$2)
A18: 綠色欄位為自動連動；黃色欄位為手動輸入。

Sheet 員工02
A1: 員工個人薪資與保費紀錄
A2: 員工姓名 | B2: ='員工設定'!B5 | D2: 員工代號 | E2: ='員工設定'!A5
A4: 月份 | B4: 薪資匯款日期 | C4: 薪資金額 | D4: 薪資明細 | E4: 健保公司負擔 | F4: 勞保公司負擔 | G4: 勞退雇主提繳 | H4: 健保個人負擔 | I4: 勞保個人負擔 | J4: 勞退個人自願提繳
A5: 46023 | E5: =SUMIFS(健保!$D$21:$D$140,健保!$A$21:$A$140,$A5,健保!$B$21:$B$140,$B$2) | F5: =SUMIFS(勞保!$D$21:$D$140,勞保!$A$21:$A$140,$A5,勞保!$B$21:$B$140,$B$2) | G5: =SUMIFS(勞退!$C$21:$C$140,勞退!$A$21:$A$140,$A5,勞退!$B$21:$B$140,$B$2) | H5: =SUMIFS(健保!$C$21:$C$140,健保!$A$21:$A$140,$A5,健保!$B$21:$B$140,$B$2) | I5: =SUMIFS(勞保!$C$21:$C$140,勞保!$A$21:$A$140,$A5,勞保!$B$21:$B$140,$B$2) | J5: =SUMIFS(勞退!$D$21:$D$140,勞退!$A$21:$A$140,$A5,勞退!$B$21:$B$140,$B$2)
A6: 46054 | E6: =SUMIFS(健保!$D$21:$D$140,健保!$A$21:$A$140,$A6,健保!$B$21:$B$140,$B$2) | F6: =SUMIFS(勞保!$D$21:$D$140,勞保!$A$21:$A$140,$A6,勞保!$B$21:$B$140,$B$2) | G6: =SUMIFS(勞退!$C$21:$C$140,勞退!$A$21:$A$140,$A6,勞退!$B$21:$B$140,$B$2) | H6: =SUMIFS(健保!$C$21:$C$140,健保!$A$21:$A$140,$A6,健保!$B$21:$B$140,$B$2) | I6: =SUMIFS(勞保!$C$21:$C$140,勞保!$A$21:$A$140,$A6,勞保!$B$21:$B$140,$B$2) | J6: =SUMIFS(勞退!$D$21:$D$140,勞退!$A$21:$A$140,$A6,勞退!$B$21:$B$140,$B$2)
A7: 46082 | E7: =SUMIFS(健保!$D$21:$D$140,健保!$A$21:$A$140,$A7,健保!$B$21:$B$140,$B$2) | F7: =SUMIFS(勞保!$D$21:$D$140,勞保!$A$21:$A$140,$A7,勞保!$B$21:$B$140,$B$2) | G7: =SUMIFS(勞退!$C$21:$C$140,勞退!$A$21:$A$140,$A7,勞退!$B$21:$B$140,$B$2) | H7: =SUMIFS(健保!$C$21:$C$140,健保!$A$21:$A$140,$A7,健保!$B$21:$B$140,$B$2) | I7: =SUMIFS(勞保!$C$21:$C$140,勞保!$A$21:$A$140,$A7,勞保!$B$21:$B$140,$B$2) | J7: =SUMIFS(勞退!$D$21:$D$140,勞退!$A$21:$A$140,$A7,勞退!$B$21:$B$140,$B$2)
A8: 46113 | E8: =SUMIFS(健保!$D$21:$D$140,健保!$A$21:$A$140,$A8,健保!$B$21:$B$140,$B$2) | F8: =SUMIFS(勞保!$D$21:$D$140,勞保!$A$21:$A$140,$A8,勞保!$B$21:$B$140,$B$2) | G8: =SUMIFS(勞退!$C$21:$C$140,勞退!$A$21:$A$140,$A8,勞退!$B$21:$B$140,$B$2) | H8: =SUMIFS(健保!$C$21:$C$140,健保!$A$21:$A$140,$A8,健保!$B$21:$B$140,$B$2) | I8: =SUMIFS(勞保!$C$21:$C$140,勞保!$A$21:$A$140,$A8,勞保!$B$21:$B$140,$B$2) | J8: =SUMIFS(勞退!$D$21:$D$140,勞退!$A$21:$A$140,$A8,勞退!$B$21:$B$140,$B$2)
A9: 46143 | E9: =SUMIFS(健保!$D$21:$D$140,健保!$A$21:$A$140,$A9,健保!$B$21:$B$140,$B$2) | F9: =SUMIFS(勞保!$D$21:$D$140,勞保!$A$21:$A$140,$A9,勞保!$B$21:$B$140,$B$2) | G9: =SUMIFS(勞退!$C$21:$C$140,勞退!$A$21:$A$140,$A9,勞退!$B$21:$B$140,$B$2) | H9: =SUMIFS(健保!$C$21:$C$140,健保!$A$21:$A$140,$A9,健保!$B$21:$B$140,$B$2) | I9: =SUMIFS(勞保!$C$21:$C$140,勞保!$A$21:$A$140,$A9,勞保!$B$21:$B$140,$B$2) | J9: =SUMIFS(勞退!$D$21:$D$140,勞退!$A$21:$A$140,$A9,勞退!$B$21:$B$140,$B$2)
A10: 46174 | E10: =SUMIFS(健保!$D$21:$D$140,健保!$A$21:$A$140,$A10,健保!$B$21:$B$140,$B$2) | F10: =SUMIFS(勞保!$D$21:$D$140,勞保!$A$21:$A$140,$A10,勞保!$B$21:$B$140,$B$2) | G10: =SUMIFS(勞退!$C$21:$C$140,勞退!$A$21:$A$140,$A10,勞退!$B$21:$B$140,$B$2) | H10: =SUMIFS(健保!$C$21:$C$140,健保!$A$21:$A$140,$A10,健保!$B$21:$B$140,$B$2) | I10: =SUMIFS(勞保!$C$21:$C$140,勞保!$A$21:$A$140,$A10,勞保!$B$21:$B$140,$B$2) | J10: =SUMIFS(勞退!$D$21:$D$140,勞退!$A$21:$A$140,$A10,勞退!$B$21:$B$140,$B$2)
A11: 46204 | E11: =SUMIFS(健保!$D$21:$D$140,健保!$A$21:$A$140,$A11,健保!$B$21:$B$140,$B$2) | F11: =SUMIFS(勞保!$D$21:$D$140,勞保!$A$21:$A$140,$A11,勞保!$B$21:$B$140,$B$2) | G11: =SUMIFS(勞退!$C$21:$C$140,勞退!$A$21:$A$140,$A11,勞退!$B$21:$B$140,$B$2) | H11: =SUMIFS(健保!$C$21:$C$140,健保!$A$21:$A$140,$A11,健保!$B$21:$B$140,$B$2) | I11: =SUMIFS(勞保!$C$21:$C$140,勞保!$A$21:$A$140,$A11,勞保!$B$21:$B$140,$B$2) | J11: =SUMIFS(勞退!$D$21:$D$140,勞退!$A$21:$A$140,$A11,勞退!$B$21:$B$140,$B$2)
A12: 46235 | E12: =SUMIFS(健保!$D$21:$D$140,健保!$A$21:$A$140,$A12,健保!$B$21:$B$140,$B$2) | F12: =SUMIFS(勞保!$D$21:$D$140,勞保!$A$21:$A$140,$A12,勞保!$B$21:$B$140,$B$2) | G12: =SUMIFS(勞退!$C$21:$C$140,勞退!$A$21:$A$140,$A12,勞退!$B$21:$B$140,$B$2) | H12: =SUMIFS(健保!$C$21:$C$140,健保!$A$21:$A$140,$A12,健保!$B$21:$B$140,$B$2) | I12: =SUMIFS(勞保!$C$21:$C$140,勞保!$A$21:$A$140,$A12,勞保!$B$21:$B$140,$B$2) | J12: =SUMIFS(勞退!$D$21:$D$140,勞退!$A$21:$A$140,$A12,勞退!$B$21:$B$140,$B$2)
A13: 46266 | E13: =SUMIFS(健保!$D$21:$D$140,健保!$A$21:$A$140,$A13,健保!$B$21:$B$140,$B$2) | F13: =SUMIFS(勞保!$D$21:$D$140,勞保!$A$21:$A$140,$A13,勞保!$B$21:$B$140,$B$2) | G13: =SUMIFS(勞退!$C$21:$C$140,勞退!$A$21:$A$140,$A13,勞退!$B$21:$B$140,$B$2) | H13: =SUMIFS(健保!$C$21:$C$140,健保!$A$21:$A$140,$A13,健保!$B$21:$B$140,$B$2) | I13: =SUMIFS(勞保!$C$21:$C$140,勞保!$A$21:$A$140,$A13,勞保!$B$21:$B$140,$B$2) | J13: =SUMIFS(勞退!$D$21:$D$140,勞退!$A$21:$A$140,$A13,勞退!$B$21:$B$140,$B$2)
A14: 46296 | E14: =SUMIFS(健保!$D$21:$D$140,健保!$A$21:$A$140,$A14,健保!$B$21:$B$140,$B$2) | F14: =SUMIFS(勞保!$D$21:$D$140,勞保!$A$21:$A$140,$A14,勞保!$B$21:$B$140,$B$2) | G14: =SUMIFS(勞退!$C$21:$C$140,勞退!$A$21:$A$140,$A14,勞退!$B$21:$B$140,$B$2) | H14: =SUMIFS(健保!$C$21:$C$140,健保!$A$21:$A$140,$A14,健保!$B$21:$B$140,$B$2) | I14: =SUMIFS(勞保!$C$21:$C$140,勞保!$A$21:$A$140,$A14,勞保!$B$21:$B$140,$B$2) | J14: =SUMIFS(勞退!$D$21:$D$140,勞退!$A$21:$A$140,$A14,勞退!$B$21:$B$140,$B$2)
A15: 46327 | E15: =SUMIFS(健保!$D$21:$D$140,健保!$A$21:$A$140,$A15,健保!$B$21:$B$140,$B$2) | F15: =SUMIFS(勞保!$D$21:$D$140,勞保!$A$21:$A$140,$A15,勞保!$B$21:$B$140,$B$2) | G15: =SUMIFS(勞退!$C$21:$C$140,勞退!$A$21:$A$140,$A15,勞退!$B$21:$B$140,$B$2) | H15: =SUMIFS(健保!$C$21:$C$140,健保!$A$21:$A$140,$A15,健保!$B$21:$B$140,$B$2) | I15: =SUMIFS(勞保!$C$21:$C$140,勞保!$A$21:$A$140,$A15,勞保!$B$21:$B$140,$B$2) | J15: =SUMIFS(勞退!$D$21:$D$140,勞退!$A$21:$A$140,$A15,勞退!$B$21:$B$140,$B$2)
A16: 46357 | E16: =SUMIFS(健保!$D$21:$D$140,健保!$A$21:$A$140,$A16,健保!$B$21:$B$140,$B$2) | F16: =SUMIFS(勞保!$D$21:$D$140,勞保!$A$21:$A$140,$A16,勞保!$B$21:$B$140,$B$2) | G16: =SUMIFS(勞退!$C$21:$C$140,勞退!$A$21:$A$140,$A16,勞退!$B$21:$B$140,$B$2) | H16: =SUMIFS(健保!$C$21:$C$140,健保!$A$21:$A$140,$A16,健保!$B$21:$B$140,$B$2) | I16: =SUMIFS(勞保!$C$21:$C$140,勞保!$A$21:$A$140,$A16,勞保!$B$21:$B$140,$B$2) | J16: =SUMIFS(勞退!$D$21:$D$140,勞退!$A$21:$A$140,$A16,勞退!$B$21:$B$140,$B$2)
A18: 綠色欄位為自動連動；黃色欄位為手動輸入。

Sheet 員工03
A1: 員工個人薪資與保費紀錄
A2: 員工姓名 | B2: ='員工設定'!B6 | D2: 員工代號 | E2: ='員工設定'!A6
A4: 月份 | B4: 薪資匯款日期 | C4: 薪資金額 | D4: 薪資明細 | E4: 健保公司負擔 | F4: 勞保公司負擔 | G4: 勞退雇主提繳 | H4: 健保個人負擔 | I4: 勞保個人負擔 | J4: 勞退個人自願提繳
A5: 46023 | E5: =SUMIFS(健保!$D$21:$D$140,健保!$A$21:$A$140,$A5,健保!$B$21:$B$140,$B$2) | F5: =SUMIFS(勞保!$D$21:$D$140,勞保!$A$21:$A$140,$A5,勞保!$B$21:$B$140,$B$2) | G5: =SUMIFS(勞退!$C$21:$C$140,勞退!$A$21:$A$140,$A5,勞退!$B$21:$B$140,$B$2) | H5: =SUMIFS(健保!$C$21:$C$140,健保!$A$21:$A$140,$A5,健保!$B$21:$B$140,$B$2) | I5: =SUMIFS(勞保!$C$21:$C$140,勞保!$A$21:$A$140,$A5,勞保!$B$21:$B$140,$B$2) | J5: =SUMIFS(勞退!$D$21:$D$140,勞退!$A$21:$A$140,$A5,勞退!$B$21:$B$140,$B$2)
A6: 46054 | E6: =SUMIFS(健保!$D$21:$D$140,健保!$A$21:$A$140,$A6,健保!$B$21:$B$140,$B$2) | F6: =SUMIFS(勞保!$D$21:$D$140,勞保!$A$21:$A$140,$A6,勞保!$B$21:$B$140,$B$2) | G6: =SUMIFS(勞退!$C$21:$C$140,勞退!$A$21:$A$140,$A6,勞退!$B$21:$B$140,$B$2) | H6: =SUMIFS(健保!$C$21:$C$140,健保!$A$21:$A$140,$A6,健保!$B$21:$B$140,$B$2) | I6: =SUMIFS(勞保!$C$21:$C$140,勞保!$A$21:$A$140,$A6,勞保!$B$21:$B$140,$B$2) | J6: =SUMIFS(勞退!$D$21:$D$140,勞退!$A$21:$A$140,$A6,勞退!$B$21:$B$140,$B$2)
A7: 46082 | E7: =SUMIFS(健保!$D$21:$D$140,健保!$A$21:$A$140,$A7,健保!$B$21:$B$140,$B$2) | F7: =SUMIFS(勞保!$D$21:$D$140,勞保!$A$21:$A$140,$A7,勞保!$B$21:$B$140,$B$2) | G7: =SUMIFS(勞退!$C$21:$C$140,勞退!$A$21:$A$140,$A7,勞退!$B$21:$B$140,$B$2) | H7: =SUMIFS(健保!$C$21:$C$140,健保!$A$21:$A$140,$A7,健保!$B$21:$B$140,$B$2) | I7: =SUMIFS(勞保!$C$21:$C$140,勞保!$A$21:$A$140,$A7,勞保!$B$21:$B$140,$B$2) | J7: =SUMIFS(勞退!$D$21:$D$140,勞退!$A$21:$A$140,$A7,勞退!$B$21:$B$140,$B$2)
A8: 46113 | E8: =SUMIFS(健保!$D$21:$D$140,健保!$A$21:$A$140,$A8,健保!$B$21:$B$140,$B$2) | F8: =SUMIFS(勞保!$D$21:$D$140,勞保!$A$21:$A$140,$A8,勞保!$B$21:$B$140,$B$2) | G8: =SUMIFS(勞退!$C$21:$C$140,勞退!$A$21:$A$140,$A8,勞退!$B$21:$B$140,$B$2) | H8: =SUMIFS(健保!$C$21:$C$140,健保!$A$21:$A$140,$A8,健保!$B$21:$B$140,$B$2) | I8: =SUMIFS(勞保!$C$21:$C$140,勞保!$A$21:$A$140,$A8,勞保!$B$21:$B$140,$B$2) | J8: =SUMIFS(勞退!$D$21:$D$140,勞退!$A$21:$A$140,$A8,勞退!$B$21:$B$140,$B$2)
A9: 46143 | E9: =SUMIFS(健保!$D$21:$D$140,健保!$A$21:$A$140,$A9,健保!$B$21:$B$140,$B$2) | F9: =SUMIFS(勞保!$D$21:$D$140,勞保!$A$21:$A$140,$A9,勞保!$B$21:$B$140,$B$2) | G9: =SUMIFS(勞退!$C$21:$C$140,勞退!$A$21:$A$140,$A9,勞退!$B$21:$B$140,$B$2) | H9: =SUMIFS(健保!$C$21:$C$140,健保!$A$21:$A$140,$A9,健保!$B$21:$B$140,$B$2) | I9: =SUMIFS(勞保!$C$21:$C$140,勞保!$A$21:$A$140,$A9,勞保!$B$21:$B$140,$B$2) | J9: =SUMIFS(勞退!$D$21:$D$140,勞退!$A$21:$A$140,$A9,勞退!$B$21:$B$140,$B$2)
A10: 46174 | E10: =SUMIFS(健保!$D$21:$D$140,健保!$A$21:$A$140,$A10,健保!$B$21:$B$140,$B$2) | F10: =SUMIFS(勞保!$D$21:$D$140,勞保!$A$21:$A$140,$A10,勞保!$B$21:$B$140,$B$2) | G10: =SUMIFS(勞退!$C$21:$C$140,勞退!$A$21:$A$140,$A10,勞退!$B$21:$B$140,$B$2) | H10: =SUMIFS(健保!$C$21:$C$140,健保!$A$21:$A$140,$A10,健保!$B$21:$B$140,$B$2) | I10: =SUMIFS(勞保!$C$21:$C$140,勞保!$A$21:$A$140,$A10,勞保!$B$21:$B$140,$B$2) | J10: =SUMIFS(勞退!$D$21:$D$140,勞退!$A$21:$A$140,$A10,勞退!$B$21:$B$140,$B$2)
A11: 46204 | E11: =SUMIFS(健保!$D$21:$D$140,健保!$A$21:$A$140,$A11,健保!$B$21:$B$140,$B$2) | F11: =SUMIFS(勞保!$D$21:$D$140,勞保!$A$21:$A$140,$A11,勞保!$B$21:$B$140,$B$2) | G11: =SUMIFS(勞退!$C$21:$C$140,勞退!$A$21:$A$140,$A11,勞退!$B$21:$B$140,$B$2) | H11: =SUMIFS(健保!$C$21:$C$140,健保!$A$21:$A$140,$A11,健保!$B$21:$B$140,$B$2) | I11: =SUMIFS(勞保!$C$21:$C$140,勞保!$A$21:$A$140,$A11,勞保!$B$21:$B$140,$B$2) | J11: =SUMIFS(勞退!$D$21:$D$140,勞退!$A$21:$A$140,$A11,勞退!$B$21:$B$140,$B$2)
A12: 46235 | E12: =SUMIFS(健保!$D$21:$D$140,健保!$A$21:$A$140,$A12,健保!$B$21:$B$140,$B$2) | F12: =SUMIFS(勞保!$D$21:$D$140,勞保!$A$21:$A$140,$A12,勞保!$B$21:$B$140,$B$2) | G12: =SUMIFS(勞退!$C$21:$C$140,勞退!$A$21:$A$140,$A12,勞退!$B$21:$B$140,$B$2) | H12: =SUMIFS(健保!$C$21:$C$140,健保!$A$21:$A$140,$A12,健保!$B$21:$B$140,$B$2) | I12: =SUMIFS(勞保!$C$21:$C$140,勞保!$A$21:$A$140,$A12,勞保!$B$21:$B$140,$B$2) | J12: =SUMIFS(勞退!$D$21:$D$140,勞退!$A$21:$A$140,$A12,勞退!$B$21:$B$140,$B$2)
A13: 46266 | E13: =SUMIFS(健保!$D$21:$D$140,健保!$A$21:$A$140,$A13,健保!$B$21:$B$140,$B$2) | F13: =SUMIFS(勞保!$D$21:$D$140,勞保!$A$21:$A$140,$A13,勞保!$B$21:$B$140,$B$2) | G13: =SUMIFS(勞退!$C$21:$C$140,勞退!$A$21:$A$140,$A13,勞退!$B$21:$B$140,$B$2) | H13: =SUMIFS(健保!$C$21:$C$140,健保!$A$21:$A$140,$A13,健保!$B$21:$B$140,$B$2) | I13: =SUMIFS(勞保!$C$21:$C$140,勞保!$A$21:$A$140,$A13,勞保!$B$21:$B$140,$B$2) | J13: =SUMIFS(勞退!$D$21:$D$140,勞退!$A$21:$A$140,$A13,勞退!$B$21:$B$140,$B$2)
A14: 46296 | E14: =SUMIFS(健保!$D$21:$D$140,健保!$A$21:$A$140,$A14,健保!$B$21:$B$140,$B$2) | F14: =SUMIFS(勞保!$D$21:$D$140,勞保!$A$21:$A$140,$A14,勞保!$B$21:$B$140,$B$2) | G14: =SUMIFS(勞退!$C$21:$C$140,勞退!$A$21:$A$140,$A14,勞退!$B$21:$B$140,$B$2) | H14: =SUMIFS(健保!$C$21:$C$140,健保!$A$21:$A$140,$A14,健保!$B$21:$B$140,$B$2) | I14: =SUMIFS(勞保!$C$21:$C$140,勞保!$A$21:$A$140,$A14,勞保!$B$21:$B$140,$B$2) | J14: =SUMIFS(勞退!$D$21:$D$140,勞退!$A$21:$A$140,$A14,勞退!$B$21:$B$140,$B$2)
A15: 46327 | E15: =SUMIFS(健保!$D$21:$D$140,健保!$A$21:$A$140,$A15,健保!$B$21:$B$140,$B$2) | F15: =SUMIFS(勞保!$D$21:$D$140,勞保!$A$21:$A$140,$A15,勞保!$B$21:$B$140,$B$2) | G15: =SUMIFS(勞退!$C$21:$C$140,勞退!$A$21:$A$140,$A15,勞退!$B$21:$B$140,$B$2) | H15: =SUMIFS(健保!$C$21:$C$140,健保!$A$21:$A$140,$A15,健保!$B$21:$B$140,$B$2) | I15: =SUMIFS(勞保!$C$21:$C$140,勞保!$A$21:$A$140,$A15,勞保!$B$21:$B$140,$B$2) | J15: =SUMIFS(勞退!$D$21:$D$140,勞退!$A$21:$A$140,$A15,勞退!$B$21:$B$140,$B$2)
A16: 46357 | E16: =SUMIFS(健保!$D$21:$D$140,健保!$A$21:$A$140,$A16,健保!$B$21:$B$140,$B$2) | F16: =SUMIFS(勞保!$D$21:$D$140,勞保!$A$21:$A$140,$A16,勞保!$B$21:$B$140,$B$2) | G16: =SUMIFS(勞退!$C$21:$C$140,勞退!$A$21:$A$140,$A16,勞退!$B$21:$B$140,$B$2) | H16: =SUMIFS(健保!$C$21:$C$140,健保!$A$21:$A$140,$A16,健保!$B$21:$B$140,$B$2) | I16: =SUMIFS(勞保!$C$21:$C$140,勞保!$A$21:$A$140,$A16,勞保!$B$21:$B$140,$B$2) | J16: =SUMIFS(勞退!$D$21:$D$140,勞退!$A$21:$A$140,$A16,勞退!$B$21:$B$140,$B$2)
A18: 綠色欄位為自動連動；黃色欄位為手動輸入。

Sheet 員工04
A1: 員工個人薪資與保費紀錄
A2: 員工姓名 | B2: ='員工設定'!B7 | D2: 員工代號 | E2: ='員工設定'!A7
A4: 月份 | B4: 薪資匯款日期 | C4: 薪資金額 | D4: 薪資明細 | E4: 健保公司負擔 | F4: 勞保公司負擔 | G4: 勞退雇主提繳 | H4: 健保個人負擔 | I4: 勞保個人負擔 | J4: 勞退個人自願提繳
A5: 46023 | E5: =SUMIFS(健保!$D$21:$D$140,健保!$A$21:$A$140,$A5,健保!$B$21:$B$140,$B$2) | F5: =SUMIFS(勞保!$D$21:$D$140,勞保!$A$21:$A$140,$A5,勞保!$B$21:$B$140,$B$2) | G5: =SUMIFS(勞退!$C$21:$C$140,勞退!$A$21:$A$140,$A5,勞退!$B$21:$B$140,$B$2) | H5: =SUMIFS(健保!$C$21:$C$140,健保!$A$21:$A$140,$A5,健保!$B$21:$B$140,$B$2) | I5: =SUMIFS(勞保!$C$21:$C$140,勞保!$A$21:$A$140,$A5,勞保!$B$21:$B$140,$B$2) | J5: =SUMIFS(勞退!$D$21:$D$140,勞退!$A$21:$A$140,$A5,勞退!$B$21:$B$140,$B$2)
A6: 46054 | E6: =SUMIFS(健保!$D$21:$D$140,健保!$A$21:$A$140,$A6,健保!$B$21:$B$140,$B$2) | F6: =SUMIFS(勞保!$D$21:$D$140,勞保!$A$21:$A$140,$A6,勞保!$B$21:$B$140,$B$2) | G6: =SUMIFS(勞退!$C$21:$C$140,勞退!$A$21:$A$140,$A6,勞退!$B$21:$B$140,$B$2) | H6: =SUMIFS(健保!$C$21:$C$140,健保!$A$21:$A$140,$A6,健保!$B$21:$B$140,$B$2) | I6: =SUMIFS(勞保!$C$21:$C$140,勞保!$A$21:$A$140,$A6,勞保!$B$21:$B$140,$B$2) | J6: =SUMIFS(勞退!$D$21:$D$140,勞退!$A$21:$A$140,$A6,勞退!$B$21:$B$140,$B$2)
A7: 46082 | E7: =SUMIFS(健保!$D$21:$D$140,健保!$A$21:$A$140,$A7,健保!$B$21:$B$140,$B$2) | F7: =SUMIFS(勞保!$D$21:$D$140,勞保!$A$21:$A$140,$A7,勞保!$B$21:$B$140,$B$2) | G7: =SUMIFS(勞退!$C$21:$C$140,勞退!$A$21:$A$140,$A7,勞退!$B$21:$B$140,$B$2) | H7: =SUMIFS(健保!$C$21:$C$140,健保!$A$21:$A$140,$A7,健保!$B$21:$B$140,$B$2) | I7: =SUMIFS(勞保!$C$21:$C$140,勞保!$A$21:$A$140,$A7,勞保!$B$21:$B$140,$B$2) | J7: =SUMIFS(勞退!$D$21:$D$140,勞退!$A$21:$A$140,$A7,勞退!$B$21:$B$140,$B$2)
A8: 46113 | E8: =SUMIFS(健保!$D$21:$D$140,健保!$A$21:$A$140,$A8,健保!$B$21:$B$140,$B$2) | F8: =SUMIFS(勞保!$D$21:$D$140,勞保!$A$21:$A$140,$A8,勞保!$B$21:$B$140,$B$2) | G8: =SUMIFS(勞退!$C$21:$C$140,勞退!$A$21:$A$140,$A8,勞退!$B$21:$B$140,$B$2) | H8: =SUMIFS(健保!$C$21:$C$140,健保!$A$21:$A$140,$A8,健保!$B$21:$B$140,$B$2) | I8: =SUMIFS(勞保!$C$21:$C$140,勞保!$A$21:$A$140,$A8,勞保!$B$21:$B$140,$B$2) | J8: =SUMIFS(勞退!$D$21:$D$140,勞退!$A$21:$A$140,$A8,勞退!$B$21:$B$140,$B$2)
A9: 46143 | E9: =SUMIFS(健保!$D$21:$D$140,健保!$A$21:$A$140,$A9,健保!$B$21:$B$140,$B$2) | F9: =SUMIFS(勞保!$D$21:$D$140,勞保!$A$21:$A$140,$A9,勞保!$B$21:$B$140,$B$2) | G9: =SUMIFS(勞退!$C$21:$C$140,勞退!$A$21:$A$140,$A9,勞退!$B$21:$B$140,$B$2) | H9: =SUMIFS(健保!$C$21:$C$140,健保!$A$21:$A$140,$A9,健保!$B$21:$B$140,$B$2) | I9: =SUMIFS(勞保!$C$21:$C$140,勞保!$A$21:$A$140,$A9,勞保!$B$21:$B$140,$B$2) | J9: =SUMIFS(勞退!$D$21:$D$140,勞退!$A$21:$A$140,$A9,勞退!$B$21:$B$140,$B$2)
A10: 46174 | E10: =SUMIFS(健保!$D$21:$D$140,健保!$A$21:$A$140,$A10,健保!$B$21:$B$140,$B$2) | F10: =SUMIFS(勞保!$D$21:$D$140,勞保!$A$21:$A$140,$A10,勞保!$B$21:$B$140,$B$2) | G10: =SUMIFS(勞退!$C$21:$C$140,勞退!$A$21:$A$140,$A10,勞退!$B$21:$B$140,$B$2) | H10: =SUMIFS(健保!$C$21:$C$140,健保!$A$21:$A$140,$A10,健保!$B$21:$B$140,$B$2) | I10: =SUMIFS(勞保!$C$21:$C$140,勞保!$A$21:$A$140,$A10,勞保!$B$21:$B$140,$B$2) | J10: =SUMIFS(勞退!$D$21:$D$140,勞退!$A$21:$A$140,$A10,勞退!$B$21:$B$140,$B$2)
A11: 46204 | E11: =SUMIFS(健保!$D$21:$D$140,健保!$A$21:$A$140,$A11,健保!$B$21:$B$140,$B$2) | F11: =SUMIFS(勞保!$D$21:$D$140,勞保!$A$21:$A$140,$A11,勞保!$B$21:$B$140,$B$2) | G11: =SUMIFS(勞退!$C$21:$C$140,勞退!$A$21:$A$140,$A11,勞退!$B$21:$B$140,$B$2) | H11: =SUMIFS(健保!$C$21:$C$140,健保!$A$21:$A$140,$A11,健保!$B$21:$B$140,$B$2) | I11: =SUMIFS(勞保!$C$21:$C$140,勞保!$A$21:$A$140,$A11,勞保!$B$21:$B$140,$B$2) | J11: =SUMIFS(勞退!$D$21:$D$140,勞退!$A$21:$A$140,$A11,勞退!$B$21:$B$140,$B$2)
A12: 46235 | E12: =SUMIFS(健保!$D$21:$D$140,健保!$A$21:$A$140,$A12,健保!$B$21:$B$140,$B$2) | F12: =SUMIFS(勞保!$D$21:$D$140,勞保!$A$21:$A$140,$A12,勞保!$B$21:$B$140,$B$2) | G12: =SUMIFS(勞退!$C$21:$C$140,勞退!$A$21:$A$140,$A12,勞退!$B$21:$B$140,$B$2) | H12: =SUMIFS(健保!$C$21:$C$140,健保!$A$21:$A$140,$A12,健保!$B$21:$B$140,$B$2) | I12: =SUMIFS(勞保!$C$21:$C$140,勞保!$A$21:$A$140,$A12,勞保!$B$21:$B$140,$B$2) | J12: =SUMIFS(勞退!$D$21:$D$140,勞退!$A$21:$A$140,$A12,勞退!$B$21:$B$140,$B$2)
A13: 46266 | E13: =SUMIFS(健保!$D$21:$D$140,健保!$A$21:$A$140,$A13,健保!$B$21:$B$140,$B$2) | F13: =SUMIFS(勞保!$D$21:$D$140,勞保!$A$21:$A$140,$A13,勞保!$B$21:$B$140,$B$2) | G13: =SUMIFS(勞退!$C$21:$C$140,勞退!$A$21:$A$140,$A13,勞退!$B$21:$B$140,$B$2) | H13: =SUMIFS(健保!$C$21:$C$140,健保!$A$21:$A$140,$A13,健保!$B$21:$B$140,$B$2) | I13: =SUMIFS(勞保!$C$21:$C$140,勞保!$A$21:$A$140,$A13,勞保!$B$21:$B$140,$B$2) | J13: =SUMIFS(勞退!$D$21:$D$140,勞退!$A$21:$A$140,$A13,勞退!$B$21:$B$140,$B$2)
A14: 46296 | E14: =SUMIFS(健保!$D$21:$D$140,健保!$A$21:$A$140,$A14,健保!$B$21:$B$140,$B$2) | F14: =SUMIFS(勞保!$D$21:$D$140,勞保!$A$21:$A$140,$A14,勞保!$B$21:$B$140,$B$2) | G14: =SUMIFS(勞退!$C$21:$C$140,勞退!$A$21:$A$140,$A14,勞退!$B$21:$B$140,$B$2) | H14: =SUMIFS(健保!$C$21:$C$140,健保!$A$21:$A$140,$A14,健保!$B$21:$B$140,$B$2) | I14: =SUMIFS(勞保!$C$21:$C$140,勞保!$A$21:$A$140,$A14,勞保!$B$21:$B$140,$B$2) | J14: =SUMIFS(勞退!$D$21:$D$140,勞退!$A$21:$A$140,$A14,勞退!$B$21:$B$140,$B$2)
A15: 46327 | E15: =SUMIFS(健保!$D$21:$D$140,健保!$A$21:$A$140,$A15,健保!$B$21:$B$140,$B$2) | F15: =SUMIFS(勞保!$D$21:$D$140,勞保!$A$21:$A$140,$A15,勞保!$B$21:$B$140,$B$2) | G15: =SUMIFS(勞退!$C$21:$C$140,勞退!$A$21:$A$140,$A15,勞退!$B$21:$B$140,$B$2) | H15: =SUMIFS(健保!$C$21:$C$140,健保!$A$21:$A$140,$A15,健保!$B$21:$B$140,$B$2) | I15: =SUMIFS(勞保!$C$21:$C$140,勞保!$A$21:$A$140,$A15,勞保!$B$21:$B$140,$B$2) | J15: =SUMIFS(勞退!$D$21:$D$140,勞退!$A$21:$A$140,$A15,勞退!$B$21:$B$140,$B$2)
A16: 46357 | E16: =SUMIFS(健保!$D$21:$D$140,健保!$A$21:$A$140,$A16,健保!$B$21:$B$140,$B$2) | F16: =SUMIFS(勞保!$D$21:$D$140,勞保!$A$21:$A$140,$A16,勞保!$B$21:$B$140,$B$2) | G16: =SUMIFS(勞退!$C$21:$C$140,勞退!$A$21:$A$140,$A16,勞退!$B$21:$B$140,$B$2) | H16: =SUMIFS(健保!$C$21:$C$140,健保!$A$21:$A$140,$A16,健保!$B$21:$B$140,$B$2) | I16: =SUMIFS(勞保!$C$21:$C$140,勞保!$A$21:$A$140,$A16,勞保!$B$21:$B$140,$B$2) | J16: =SUMIFS(勞退!$D$21:$D$140,勞退!$A$21:$A$140,$A16,勞退!$B$21:$B$140,$B$2)
A18: 綠色欄位為自動連動；黃色欄位為手動輸入。

Sheet 員工05
A1: 員工個人薪資與保費紀錄
A2: 員工姓名 | B2: ='員工設定'!B8 | D2: 員工代號 | E2: ='員工設定'!A8
A4: 月份 | B4: 薪資匯款日期 | C4: 薪資金額 | D4: 薪資明細 | E4: 健保公司負擔 | F4: 勞保公司負擔 | G4: 勞退雇主提繳 | H4: 健保個人負擔 | I4: 勞保個人負擔 | J4: 勞退個人自願提繳
A5: 46023 | E5: =SUMIFS(健保!$D$21:$D$140,健保!$A$21:$A$140,$A5,健保!$B$21:$B$140,$B$2) | F5: =SUMIFS(勞保!$D$21:$D$140,勞保!$A$21:$A$140,$A5,勞保!$B$21:$B$140,$B$2) | G5: =SUMIFS(勞退!$C$21:$C$140,勞退!$A$21:$A$140,$A5,勞退!$B$21:$B$140,$B$2) | H5: =SUMIFS(健保!$C$21:$C$140,健保!$A$21:$A$140,$A5,健保!$B$21:$B$140,$B$2) | I5: =SUMIFS(勞保!$C$21:$C$140,勞保!$A$21:$A$140,$A5,勞保!$B$21:$B$140,$B$2) | J5: =SUMIFS(勞退!$D$21:$D$140,勞退!$A$21:$A$140,$A5,勞退!$B$21:$B$140,$B$2)
A6: 46054 | E6: =SUMIFS(健保!$D$21:$D$140,健保!$A$21:$A$140,$A6,健保!$B$21:$B$140,$B$2) | F6: =SUMIFS(勞保!$D$21:$D$140,勞保!$A$21:$A$140,$A6,勞保!$B$21:$B$140,$B$2) | G6: =SUMIFS(勞退!$C$21:$C$140,勞退!$A$21:$A$140,$A6,勞退!$B$21:$B$140,$B$2) | H6: =SUMIFS(健保!$C$21:$C$140,健保!$A$21:$A$140,$A6,健保!$B$21:$B$140,$B$2) | I6: =SUMIFS(勞保!$C$21:$C$140,勞保!$A$21:$A$140,$A6,勞保!$B$21:$B$140,$B$2) | J6: =SUMIFS(勞退!$D$21:$D$140,勞退!$A$21:$A$140,$A6,勞退!$B$21:$B$140,$B$2)
A7: 46082 | E7: =SUMIFS(健保!$D$21:$D$140,健保!$A$21:$A$140,$A7,健保!$B$21:$B$140,$B$2) | F7: =SUMIFS(勞保!$D$21:$D$140,勞保!$A$21:$A$140,$A7,勞保!$B$21:$B$140,$B$2) | G7: =SUMIFS(勞退!$C$21:$C$140,勞退!$A$21:$A$140,$A7,勞退!$B$21:$B$140,$B$2) | H7: =SUMIFS(健保!$C$21:$C$140,健保!$A$21:$A$140,$A7,健保!$B$21:$B$140,$B$2) | I7: =SUMIFS(勞保!$C$21:$C$140,勞保!$A$21:$A$140,$A7,勞保!$B$21:$B$140,$B$2) | J7: =SUMIFS(勞退!$D$21:$D$140,勞退!$A$21:$A$140,$A7,勞退!$B$21:$B$140,$B$2)
A8: 46113 | E8: =SUMIFS(健保!$D$21:$D$140,健保!$A$21:$A$140,$A8,健保!$B$21:$B$140,$B$2) | F8: =SUMIFS(勞保!$D$21:$D$140,勞保!$A$21:$A$140,$A8,勞保!$B$21:$B$140,$B$2) | G8: =SUMIFS(勞退!$C$21:$C$140,勞退!$A$21:$A$140,$A8,勞退!$B$21:$B$140,$B$2) | H8: =SUMIFS(健保!$C$21:$C$140,健保!$A$21:$A$140,$A8,健保!$B$21:$B$140,$B$2) | I8: =SUMIFS(勞保!$C$21:$C$140,勞保!$A$21:$A$140,$A8,勞保!$B$21:$B$140,$B$2) | J8: =SUMIFS(勞退!$D$21:$D$140,勞退!$A$21:$A$140,$A8,勞退!$B$21:$B$140,$B$2)
A9: 46143 | E9: =SUMIFS(健保!$D$21:$D$140,健保!$A$21:$A$140,$A9,健保!$B$21:$B$140,$B$2) | F9: =SUMIFS(勞保!$D$21:$D$140,勞保!$A$21:$A$140,$A9,勞保!$B$21:$B$140,$B$2) | G9: =SUMIFS(勞退!$C$21:$C$140,勞退!$A$21:$A$140,$A9,勞退!$B$21:$B$140,$B$2) | H9: =SUMIFS(健保!$C$21:$C$140,健保!$A$21:$A$140,$A9,健保!$B$21:$B$140,$B$2) | I9: =SUMIFS(勞保!$C$21:$C$140,勞保!$A$21:$A$140,$A9,勞保!$B$21:$B$140,$B$2) | J9: =SUMIFS(勞退!$D$21:$D$140,勞退!$A$21:$A$140,$A9,勞退!$B$21:$B$140,$B$2)
A10: 46174 | E10: =SUMIFS(健保!$D$21:$D$140,健保!$A$21:$A$140,$A10,健保!$B$21:$B$140,$B$2) | F10: =SUMIFS(勞保!$D$21:$D$140,勞保!$A$21:$A$140,$A10,勞保!$B$21:$B$140,$B$2) | G10: =SUMIFS(勞退!$C$21:$C$140,勞退!$A$21:$A$140,$A10,勞退!$B$21:$B$140,$B$2) | H10: =SUMIFS(健保!$C$21:$C$140,健保!$A$21:$A$140,$A10,健保!$B$21:$B$140,$B$2) | I10: =SUMIFS(勞保!$C$21:$C$140,勞保!$A$21:$A$140,$A10,勞保!$B$21:$B$140,$B$2) | J10: =SUMIFS(勞退!$D$21:$D$140,勞退!$A$21:$A$140,$A10,勞退!$B$21:$B$140,$B$2)
A11: 46204 | E11: =SUMIFS(健保!$D$21:$D$140,健保!$A$21:$A$140,$A11,健保!$B$21:$B$140,$B$2) | F11: =SUMIFS(勞保!$D$21:$D$140,勞保!$A$21:$A$140,$A11,勞保!$B$21:$B$140,$B$2) | G11: =SUMIFS(勞退!$C$21:$C$140,勞退!$A$21:$A$140,$A11,勞退!$B$21:$B$140,$B$2) | H11: =SUMIFS(健保!$C$21:$C$140,健保!$A$21:$A$140,$A11,健保!$B$21:$B$140,$B$2) | I11: =SUMIFS(勞保!$C$21:$C$140,勞保!$A$21:$A$140,$A11,勞保!$B$21:$B$140,$B$2) | J11: =SUMIFS(勞退!$D$21:$D$140,勞退!$A$21:$A$140,$A11,勞退!$B$21:$B$140,$B$2)
A12: 46235 | E12: =SUMIFS(健保!$D$21:$D$140,健保!$A$21:$A$140,$A12,健保!$B$21:$B$140,$B$2) | F12: =SUMIFS(勞保!$D$21:$D$140,勞保!$A$21:$A$140,$A12,勞保!$B$21:$B$140,$B$2) | G12: =SUMIFS(勞退!$C$21:$C$140,勞退!$A$21:$A$140,$A12,勞退!$B$21:$B$140,$B$2) | H12: =SUMIFS(健保!$C$21:$C$140,健保!$A$21:$A$140,$A12,健保!$B$21:$B$140,$B$2) | I12: =SUMIFS(勞保!$C$21:$C$140,勞保!$A$21:$A$140,$A12,勞保!$B$21:$B$140,$B$2) | J12: =SUMIFS(勞退!$D$21:$D$140,勞退!$A$21:$A$140,$A12,勞退!$B$21:$B$140,$B$2)
A13: 46266 | E13: =SUMIFS(健保!$D$21:$D$140,健保!$A$21:$A$140,$A13,健保!$B$21:$B$140,$B$2) | F13: =SUMIFS(勞保!$D$21:$D$140,勞保!$A$21:$A$140,$A13,勞保!$B$21:$B$140,$B$2) | G13: =SUMIFS(勞退!$C$21:$C$140,勞退!$A$21:$A$140,$A13,勞退!$B$21:$B$140,$B$2) | H13: =SUMIFS(健保!$C$21:$C$140,健保!$A$21:$A$140,$A13,健保!$B$21:$B$140,$B$2) | I13: =SUMIFS(勞保!$C$21:$C$140,勞保!$A$21:$A$140,$A13,勞保!$B$21:$B$140,$B$2) | J13: =SUMIFS(勞退!$D$21:$D$140,勞退!$A$21:$A$140,$A13,勞退!$B$21:$B$140,$B$2)
A14: 46296 | E14: =SUMIFS(健保!$D$21:$D$140,健保!$A$21:$A$140,$A14,健保!$B$21:$B$140,$B$2) | F14: =SUMIFS(勞保!$D$21:$D$140,勞保!$A$21:$A$140,$A14,勞保!$B$21:$B$140,$B$2) | G14: =SUMIFS(勞退!$C$21:$C$140,勞退!$A$21:$A$140,$A14,勞退!$B$21:$B$140,$B$2) | H14: =SUMIFS(健保!$C$21:$C$140,健保!$A$21:$A$140,$A14,健保!$B$21:$B$140,$B$2) | I14: =SUMIFS(勞保!$C$21:$C$140,勞保!$A$21:$A$140,$A14,勞保!$B$21:$B$140,$B$2) | J14: =SUMIFS(勞退!$D$21:$D$140,勞退!$A$21:$A$140,$A14,勞退!$B$21:$B$140,$B$2)
A15: 46327 | E15: =SUMIFS(健保!$D$21:$D$140,健保!$A$21:$A$140,$A15,健保!$B$21:$B$140,$B$2) | F15: =SUMIFS(勞保!$D$21:$D$140,勞保!$A$21:$A$140,$A15,勞保!$B$21:$B$140,$B$2) | G15: =SUMIFS(勞退!$C$21:$C$140,勞退!$A$21:$A$140,$A15,勞退!$B$21:$B$140,$B$2) | H15: =SUMIFS(健保!$C$21:$C$140,健保!$A$21:$A$140,$A15,健保!$B$21:$B$140,$B$2) | I15: =SUMIFS(勞保!$C$21:$C$140,勞保!$A$21:$A$140,$A15,勞保!$B$21:$B$140,$B$2) | J15: =SUMIFS(勞退!$D$21:$D$140,勞退!$A$21:$A$140,$A15,勞退!$B$21:$B$140,$B$2)
A16: 46357 | E16: =SUMIFS(健保!$D$21:$D$140,健保!$A$21:$A$140,$A16,健保!$B$21:$B$140,$B$2) | F16: =SUMIFS(勞保!$D$21:$D$140,勞保!$A$21:$A$140,$A16,勞保!$B$21:$B$140,$B$2) | G16: =SUMIFS(勞退!$C$21:$C$140,勞退!$A$21:$A$140,$A16,勞退!$B$21:$B$140,$B$2) | H16: =SUMIFS(健保!$C$21:$C$140,健保!$A$21:$A$140,$A16,健保!$B$21:$B$140,$B$2) | I16: =SUMIFS(勞保!$C$21:$C$140,勞保!$A$21:$A$140,$A16,勞保!$B$21:$B$140,$B$2) | J16: =SUMIFS(勞退!$D$21:$D$140,勞退!$A$21:$A$140,$A16,勞退!$B$21:$B$140,$B$2)
A18: 綠色欄位為自動連動；黃色欄位為手動輸入。

Sheet 員工06
A1: 員工個人薪資與保費紀錄
A2: 員工姓名 | B2: ='員工設定'!B9 | D2: 員工代號 | E2: ='員工設定'!A9
A4: 月份 | B4: 薪資匯款日期 | C4: 薪資金額 | D4: 薪資明細 | E4: 健保公司負擔 | F4: 勞保公司負擔 | G4: 勞退雇主提繳 | H4: 健保個人負擔 | I4: 勞保個人負擔 | J4: 勞退個人自願提繳
A5: 46023 | E5: =SUMIFS(健保!$D$21:$D$140,健保!$A$21:$A$140,$A5,健保!$B$21:$B$140,$B$2) | F5: =SUMIFS(勞保!$D$21:$D$140,勞保!$A$21:$A$140,$A5,勞保!$B$21:$B$140,$B$2) | G5: =SUMIFS(勞退!$C$21:$C$140,勞退!$A$21:$A$140,$A5,勞退!$B$21:$B$140,$B$2) | H5: =SUMIFS(健保!$C$21:$C$140,健保!$A$21:$A$140,$A5,健保!$B$21:$B$140,$B$2) | I5: =SUMIFS(勞保!$C$21:$C$140,勞保!$A$21:$A$140,$A5,勞保!$B$21:$B$140,$B$2) | J5: =SUMIFS(勞退!$D$21:$D$140,勞退!$A$21:$A$140,$A5,勞退!$B$21:$B$140,$B$2)
A6: 46054 | E6: =SUMIFS(健保!$D$21:$D$140,健保!$A$21:$A$140,$A6,健保!$B$21:$B$140,$B$2) | F6: =SUMIFS(勞保!$D$21:$D$140,勞保!$A$21:$A$140,$A6,勞保!$B$21:$B$140,$B$2) | G6: =SUMIFS(勞退!$C$21:$C$140,勞退!$A$21:$A$140,$A6,勞退!$B$21:$B$140,$B$2) | H6: =SUMIFS(健保!$C$21:$C$140,健保!$A$21:$A$140,$A6,健保!$B$21:$B$140,$B$2) | I6: =SUMIFS(勞保!$C$21:$C$140,勞保!$A$21:$A$140,$A6,勞保!$B$21:$B$140,$B$2) | J6: =SUMIFS(勞退!$D$21:$D$140,勞退!$A$21:$A$140,$A6,勞退!$B$21:$B$140,$B$2)
A7: 46082 | E7: =SUMIFS(健保!$D$21:$D$140,健保!$A$21:$A$140,$A7,健保!$B$21:$B$140,$B$2) | F7: =SUMIFS(勞保!$D$21:$D$140,勞保!$A$21:$A$140,$A7,勞保!$B$21:$B$140,$B$2) | G7: =SUMIFS(勞退!$C$21:$C$140,勞退!$A$21:$A$140,$A7,勞退!$B$21:$B$140,$B$2) | H7: =SUMIFS(健保!$C$21:$C$140,健保!$A$21:$A$140,$A7,健保!$B$21:$B$140,$B$2) | I7: =SUMIFS(勞保!$C$21:$C$140,勞保!$A$21:$A$140,$A7,勞保!$B$21:$B$140,$B$2) | J7: =SUMIFS(勞退!$D$21:$D$140,勞退!$A$21:$A$140,$A7,勞退!$B$21:$B$140,$B$2)
A8: 46113 | E8: =SUMIFS(健保!$D$21:$D$140,健保!$A$21:$A$140,$A8,健保!$B$21:$B$140,$B$2) | F8: =SUMIFS(勞保!$D$21:$D$140,勞保!$A$21:$A$140,$A8,勞保!$B$21:$B$140,$B$2) | G8: =SUMIFS(勞退!$C$21:$C$140,勞退!$A$21:$A$140,$A8,勞退!$B$21:$B$140,$B$2) | H8: =SUMIFS(健保!$C$21:$C$140,健保!$A$21:$A$140,$A8,健保!$B$21:$B$140,$B$2) | I8: =SUMIFS(勞保!$C$21:$C$140,勞保!$A$21:$A$140,$A8,勞保!$B$21:$B$140,$B$2) | J8: =SUMIFS(勞退!$D$21:$D$140,勞退!$A$21:$A$140,$A8,勞退!$B$21:$B$140,$B$2)
A9: 46143 | E9: =SUMIFS(健保!$D$21:$D$140,健保!$A$21:$A$140,$A9,健保!$B$21:$B$140,$B$2) | F9: =SUMIFS(勞保!$D$21:$D$140,勞保!$A$21:$A$140,$A9,勞保!$B$21:$B$140,$B$2) | G9: =SUMIFS(勞退!$C$21:$C$140,勞退!$A$21:$A$140,$A9,勞退!$B$21:$B$140,$B$2) | H9: =SUMIFS(健保!$C$21:$C$140,健保!$A$21:$A$140,$A9,健保!$B$21:$B$140,$B$2) | I9: =SUMIFS(勞保!$C$21:$C$140,勞保!$A$21:$A$140,$A9,勞保!$B$21:$B$140,$B$2) | J9: =SUMIFS(勞退!$D$21:$D$140,勞退!$A$21:$A$140,$A9,勞退!$B$21:$B$140,$B$2)
A10: 46174 | E10: =SUMIFS(健保!$D$21:$D$140,健保!$A$21:$A$140,$A10,健保!$B$21:$B$140,$B$2) | F10: =SUMIFS(勞保!$D$21:$D$140,勞保!$A$21:$A$140,$A10,勞保!$B$21:$B$140,$B$2) | G10: =SUMIFS(勞退!$C$21:$C$140,勞退!$A$21:$A$140,$A10,勞退!$B$21:$B$140,$B$2) | H10: =SUMIFS(健保!$C$21:$C$140,健保!$A$21:$A$140,$A10,健保!$B$21:$B$140,$B$2) | I10: =SUMIFS(勞保!$C$21:$C$140,勞保!$A$21:$A$140,$A10,勞保!$B$21:$B$140,$B$2) | J10: =SUMIFS(勞退!$D$21:$D$140,勞退!$A$21:$A$140,$A10,勞退!$B$21:$B$140,$B$2)
A11: 46204 | E11: =SUMIFS(健保!$D$21:$D$140,健保!$A$21:$A$140,$A11,健保!$B$21:$B$140,$B$2) | F11: =SUMIFS(勞保!$D$21:$D$140,勞保!$A$21:$A$140,$A11,勞保!$B$21:$B$140,$B$2) | G11: =SUMIFS(勞退!$C$21:$C$140,勞退!$A$21:$A$140,$A11,勞退!$B$21:$B$140,$B$2) | H11: =SUMIFS(健保!$C$21:$C$140,健保!$A$21:$A$140,$A11,健保!$B$21:$B$140,$B$2) | I11: =SUMIFS(勞保!$C$21:$C$140,勞保!$A$21:$A$140,$A11,勞保!$B$21:$B$140,$B$2) | J11: =SUMIFS(勞退!$D$21:$D$140,勞退!$A$21:$A$140,$A11,勞退!$B$21:$B$140,$B$2)
A12: 46235 | E12: =SUMIFS(健保!$D$21:$D$140,健保!$A$21:$A$140,$A12,健保!$B$21:$B$140,$B$2) | F12: =SUMIFS(勞保!$D$21:$D$140,勞保!$A$21:$A$140,$A12,勞保!$B$21:$B$140,$B$2) | G12: =SUMIFS(勞退!$C$21:$C$140,勞退!$A$21:$A$140,$A12,勞退!$B$21:$B$140,$B$2) | H12: =SUMIFS(健保!$C$21:$C$140,健保!$A$21:$A$140,$A12,健保!$B$21:$B$140,$B$2) | I12: =SUMIFS(勞保!$C$21:$C$140,勞保!$A$21:$A$140,$A12,勞保!$B$21:$B$140,$B$2) | J12: =SUMIFS(勞退!$D$21:$D$140,勞退!$A$21:$A$140,$A12,勞退!$B$21:$B$140,$B$2)
A13: 46266 | E13: =SUMIFS(健保!$D$21:$D$140,健保!$A$21:$A$140,$A13,健保!$B$21:$B$140,$B$2) | F13: =SUMIFS(勞保!$D$21:$D$140,勞保!$A$21:$A$140,$A13,勞保!$B$21:$B$140,$B$2) | G13: =SUMIFS(勞退!$C$21:$C$140,勞退!$A$21:$A$140,$A13,勞退!$B$21:$B$140,$B$2) | H13: =SUMIFS(健保!$C$21:$C$140,健保!$A$21:$A$140,$A13,健保!$B$21:$B$140,$B$2) | I13: =SUMIFS(勞保!$C$21:$C$140,勞保!$A$21:$A$140,$A13,勞保!$B$21:$B$140,$B$2) | J13: =SUMIFS(勞退!$D$21:$D$140,勞退!$A$21:$A$140,$A13,勞退!$B$21:$B$140,$B$2)
A14: 46296 | E14: =SUMIFS(健保!$D$21:$D$140,健保!$A$21:$A$140,$A14,健保!$B$21:$B$140,$B$2) | F14: =SUMIFS(勞保!$D$21:$D$140,勞保!$A$21:$A$140,$A14,勞保!$B$21:$B$140,$B$2) | G14: =SUMIFS(勞退!$C$21:$C$140,勞退!$A$21:$A$140,$A14,勞退!$B$21:$B$140,$B$2) | H14: =SUMIFS(健保!$C$21:$C$140,健保!$A$21:$A$140,$A14,健保!$B$21:$B$140,$B$2) | I14: =SUMIFS(勞保!$C$21:$C$140,勞保!$A$21:$A$140,$A14,勞保!$B$21:$B$140,$B$2) | J14: =SUMIFS(勞退!$D$21:$D$140,勞退!$A$21:$A$140,$A14,勞退!$B$21:$B$140,$B$2)
A15: 46327 | E15: =SUMIFS(健保!$D$21:$D$140,健保!$A$21:$A$140,$A15,健保!$B$21:$B$140,$B$2) | F15: =SUMIFS(勞保!$D$21:$D$140,勞保!$A$21:$A$140,$A15,勞保!$B$21:$B$140,$B$2) | G15: =SUMIFS(勞退!$C$21:$C$140,勞退!$A$21:$A$140,$A15,勞退!$B$21:$B$140,$B$2) | H15: =SUMIFS(健保!$C$21:$C$140,健保!$A$21:$A$140,$A15,健保!$B$21:$B$140,$B$2) | I15: =SUMIFS(勞保!$C$21:$C$140,勞保!$A$21:$A$140,$A15,勞保!$B$21:$B$140,$B$2) | J15: =SUMIFS(勞退!$D$21:$D$140,勞退!$A$21:$A$140,$A15,勞退!$B$21:$B$140,$B$2)
A16: 46357 | E16: =SUMIFS(健保!$D$21:$D$140,健保!$A$21:$A$140,$A16,健保!$B$21:$B$140,$B$2) | F16: =SUMIFS(勞保!$D$21:$D$140,勞保!$A$21:$A$140,$A16,勞保!$B$21:$B$140,$B$2) | G16: =SUMIFS(勞退!$C$21:$C$140,勞退!$A$21:$A$140,$A16,勞退!$B$21:$B$140,$B$2) | H16: =SUMIFS(健保!$C$21:$C$140,健保!$A$21:$A$140,$A16,健保!$B$21:$B$140,$B$2) | I16: =SUMIFS(勞保!$C$21:$C$140,勞保!$A$21:$A$140,$A16,勞保!$B$21:$B$140,$B$2) | J16: =SUMIFS(勞退!$D$21:$D$140,勞退!$A$21:$A$140,$A16,勞退!$B$21:$B$140,$B$2)
A18: 綠色欄位為自動連動；黃色欄位為手動輸入。

Sheet 員工07
A1: 員工個人薪資與保費紀錄
A2: 員工姓名 | B2: ='員工設定'!B10 | D2: 員工代號 | E2: ='員工設定'!A10
A4: 月份 | B4: 薪資匯款日期 | C4: 薪資金額 | D4: 薪資明細 | E4: 健保公司負擔 | F4: 勞保公司負擔 | G4: 勞退雇主提繳 | H4: 健保個人負擔 | I4: 勞保個人負擔 | J4: 勞退個人自願提繳
A5: 46023 | E5: =SUMIFS(健保!$D$21:$D$140,健保!$A$21:$A$140,$A5,健保!$B$21:$B$140,$B$2) | F5: =SUMIFS(勞保!$D$21:$D$140,勞保!$A$21:$A$140,$A5,勞保!$B$21:$B$140,$B$2) | G5: =SUMIFS(勞退!$C$21:$C$140,勞退!$A$21:$A$140,$A5,勞退!$B$21:$B$140,$B$2) | H5: =SUMIFS(健保!$C$21:$C$140,健保!$A$21:$A$140,$A5,健保!$B$21:$B$140,$B$2) | I5: =SUMIFS(勞保!$C$21:$C$140,勞保!$A$21:$A$140,$A5,勞保!$B$21:$B$140,$B$2) | J5: =SUMIFS(勞退!$D$21:$D$140,勞退!$A$21:$A$140,$A5,勞退!$B$21:$B$140,$B$2)
A6: 46054 | E6: =SUMIFS(健保!$D$21:$D$140,健保!$A$21:$A$140,$A6,健保!$B$21:$B$140,$B$2) | F6: =SUMIFS(勞保!$D$21:$D$140,勞保!$A$21:$A$140,$A6,勞保!$B$21:$B$140,$B$2) | G6: =SUMIFS(勞退!$C$21:$C$140,勞退!$A$21:$A$140,$A6,勞退!$B$21:$B$140,$B$2) | H6: =SUMIFS(健保!$C$21:$C$140,健保!$A$21:$A$140,$A6,健保!$B$21:$B$140,$B$2) | I6: =SUMIFS(勞保!$C$21:$C$140,勞保!$A$21:$A$140,$A6,勞保!$B$21:$B$140,$B$2) | J6: =SUMIFS(勞退!$D$21:$D$140,勞退!$A$21:$A$140,$A6,勞退!$B$21:$B$140,$B$2)
A7: 46082 | E7: =SUMIFS(健保!$D$21:$D$140,健保!$A$21:$A$140,$A7,健保!$B$21:$B$140,$B$2) | F7: =SUMIFS(勞保!$D$21:$D$140,勞保!$A$21:$A$140,$A7,勞保!$B$21:$B$140,$B$2) | G7: =SUMIFS(勞退!$C$21:$C$140,勞退!$A$21:$A$140,$A7,勞退!$B$21:$B$140,$B$2) | H7: =SUMIFS(健保!$C$21:$C$140,健保!$A$21:$A$140,$A7,健保!$B$21:$B$140,$B$2) | I7: =SUMIFS(勞保!$C$21:$C$140,勞保!$A$21:$A$140,$A7,勞保!$B$21:$B$140,$B$2) | J7: =SUMIFS(勞退!$D$21:$D$140,勞退!$A$21:$A$140,$A7,勞退!$B$21:$B$140,$B$2)
A8: 46113 | E8: =SUMIFS(健保!$D$21:$D$140,健保!$A$21:$A$140,$A8,健保!$B$21:$B$140,$B$2) | F8: =SUMIFS(勞保!$D$21:$D$140,勞保!$A$21:$A$140,$A8,勞保!$B$21:$B$140,$B$2) | G8: =SUMIFS(勞退!$C$21:$C$140,勞退!$A$21:$A$140,$A8,勞退!$B$21:$B$140,$B$2) | H8: =SUMIFS(健保!$C$21:$C$140,健保!$A$21:$A$140,$A8,健保!$B$21:$B$140,$B$2) | I8: =SUMIFS(勞保!$C$21:$C$140,勞保!$A$21:$A$140,$A8,勞保!$B$21:$B$140,$B$2) | J8: =SUMIFS(勞退!$D$21:$D$140,勞退!$A$21:$A$140,$A8,勞退!$B$21:$B$140,$B$2)
A9: 46143 | E9: =SUMIFS(健保!$D$21:$D$140,健保!$A$21:$A$140,$A9,健保!$B$21:$B$140,$B$2) | F9: =SUMIFS(勞保!$D$21:$D$140,勞保!$A$21:$A$140,$A9,勞保!$B$21:$B$140,$B$2) | G9: =SUMIFS(勞退!$C$21:$C$140,勞退!$A$21:$A$140,$A9,勞退!$B$21:$B$140,$B$2) | H9: =SUMIFS(健保!$C$21:$C$140,健保!$A$21:$A$140,$A9,健保!$B$21:$B$140,$B$2) | I9: =SUMIFS(勞保!$C$21:$C$140,勞保!$A$21:$A$140,$A9,勞保!$B$21:$B$140,$B$2) | J9: =SUMIFS(勞退!$D$21:$D$140,勞退!$A$21:$A$140,$A9,勞退!$B$21:$B$140,$B$2)
A10: 46174 | E10: =SUMIFS(健保!$D$21:$D$140,健保!$A$21:$A$140,$A10,健保!$B$21:$B$140,$B$2) | F10: =SUMIFS(勞保!$D$21:$D$140,勞保!$A$21:$A$140,$A10,勞保!$B$21:$B$140,$B$2) | G10: =SUMIFS(勞退!$C$21:$C$140,勞退!$A$21:$A$140,$A10,勞退!$B$21:$B$140,$B$2) | H10: =SUMIFS(健保!$C$21:$C$140,健保!$A$21:$A$140,$A10,健保!$B$21:$B$140,$B$2) | I10: =SUMIFS(勞保!$C$21:$C$140,勞保!$A$21:$A$140,$A10,勞保!$B$21:$B$140,$B$2) | J10: =SUMIFS(勞退!$D$21:$D$140,勞退!$A$21:$A$140,$A10,勞退!$B$21:$B$140,$B$2)
A11: 46204 | E11: =SUMIFS(健保!$D$21:$D$140,健保!$A$21:$A$140,$A11,健保!$B$21:$B$140,$B$2) | F11: =SUMIFS(勞保!$D$21:$D$140,勞保!$A$21:$A$140,$A11,勞保!$B$21:$B$140,$B$2) | G11: =SUMIFS(勞退!$C$21:$C$140,勞退!$A$21:$A$140,$A11,勞退!$B$21:$B$140,$B$2) | H11: =SUMIFS(健保!$C$21:$C$140,健保!$A$21:$A$140,$A11,健保!$B$21:$B$140,$B$2) | I11: =SUMIFS(勞保!$C$21:$C$140,勞保!$A$21:$A$140,$A11,勞保!$B$21:$B$140,$B$2) | J11: =SUMIFS(勞退!$D$21:$D$140,勞退!$A$21:$A$140,$A11,勞退!$B$21:$B$140,$B$2)
A12: 46235 | E12: =SUMIFS(健保!$D$21:$D$140,健保!$A$21:$A$140,$A12,健保!$B$21:$B$140,$B$2) | F12: =SUMIFS(勞保!$D$21:$D$140,勞保!$A$21:$A$140,$A12,勞保!$B$21:$B$140,$B$2) | G12: =SUMIFS(勞退!$C$21:$C$140,勞退!$A$21:$A$140,$A12,勞退!$B$21:$B$140,$B$2) | H12: =SUMIFS(健保!$C$21:$C$140,健保!$A$21:$A$140,$A12,健保!$B$21:$B$140,$B$2) | I12: =SUMIFS(勞保!$C$21:$C$140,勞保!$A$21:$A$140,$A12,勞保!$B$21:$B$140,$B$2) | J12: =SUMIFS(勞退!$D$21:$D$140,勞退!$A$21:$A$140,$A12,勞退!$B$21:$B$140,$B$2)
A13: 46266 | E13: =SUMIFS(健保!$D$21:$D$140,健保!$A$21:$A$140,$A13,健保!$B$21:$B$140,$B$2) | F13: =SUMIFS(勞保!$D$21:$D$140,勞保!$A$21:$A$140,$A13,勞保!$B$21:$B$140,$B$2) | G13: =SUMIFS(勞退!$C$21:$C$140,勞退!$A$21:$A$140,$A13,勞退!$B$21:$B$140,$B$2) | H13: =SUMIFS(健保!$C$21:$C$140,健保!$A$21:$A$140,$A13,健保!$B$21:$B$140,$B$2) | I13: =SUMIFS(勞保!$C$21:$C$140,勞保!$A$21:$A$140,$A13,勞保!$B$21:$B$140,$B$2) | J13: =SUMIFS(勞退!$D$21:$D$140,勞退!$A$21:$A$140,$A13,勞退!$B$21:$B$140,$B$2)
A14: 46296 | E14: =SUMIFS(健保!$D$21:$D$140,健保!$A$21:$A$140,$A14,健保!$B$21:$B$140,$B$2) | F14: =SUMIFS(勞保!$D$21:$D$140,勞保!$A$21:$A$140,$A14,勞保!$B$21:$B$140,$B$2) | G14: =SUMIFS(勞退!$C$21:$C$140,勞退!$A$21:$A$140,$A14,勞退!$B$21:$B$140,$B$2) | H14: =SUMIFS(健保!$C$21:$C$140,健保!$A$21:$A$140,$A14,健保!$B$21:$B$140,$B$2) | I14: =SUMIFS(勞保!$C$21:$C$140,勞保!$A$21:$A$140,$A14,勞保!$B$21:$B$140,$B$2) | J14: =SUMIFS(勞退!$D$21:$D$140,勞退!$A$21:$A$140,$A14,勞退!$B$21:$B$140,$B$2)
A15: 46327 | E15: =SUMIFS(健保!$D$21:$D$140,健保!$A$21:$A$140,$A15,健保!$B$21:$B$140,$B$2) | F15: =SUMIFS(勞保!$D$21:$D$140,勞保!$A$21:$A$140,$A15,勞保!$B$21:$B$140,$B$2) | G15: =SUMIFS(勞退!$C$21:$C$140,勞退!$A$21:$A$140,$A15,勞退!$B$21:$B$140,$B$2) | H15: =SUMIFS(健保!$C$21:$C$140,健保!$A$21:$A$140,$A15,健保!$B$21:$B$140,$B$2) | I15: =SUMIFS(勞保!$C$21:$C$140,勞保!$A$21:$A$140,$A15,勞保!$B$21:$B$140,$B$2) | J15: =SUMIFS(勞退!$D$21:$D$140,勞退!$A$21:$A$140,$A15,勞退!$B$21:$B$140,$B$2)
A16: 46357 | E16: =SUMIFS(健保!$D$21:$D$140,健保!$A$21:$A$140,$A16,健保!$B$21:$B$140,$B$2) | F16: =SUMIFS(勞保!$D$21:$D$140,勞保!$A$21:$A$140,$A16,勞保!$B$21:$B$140,$B$2) | G16: =SUMIFS(勞退!$C$21:$C$140,勞退!$A$21:$A$140,$A16,勞退!$B$21:$B$140,$B$2) | H16: =SUMIFS(健保!$C$21:$C$140,健保!$A$21:$A$140,$A16,健保!$B$21:$B$140,$B$2) | I16: =SUMIFS(勞保!$C$21:$C$140,勞保!$A$21:$A$140,$A16,勞保!$B$21:$B$140,$B$2) | J16: =SUMIFS(勞退!$D$21:$D$140,勞退!$A$21:$A$140,$A16,勞退!$B$21:$B$140,$B$2)
A18: 綠色欄位為自動連動；黃色欄位為手動輸入。

Sheet 員工08
A1: 員工個人薪資與保費紀錄
A2: 員工姓名 | B2: ='員工設定'!B11 | D2: 員工代號 | E2: ='員工設定'!A11
A4: 月份 | B4: 薪資匯款日期 | C4: 薪資金額 | D4: 薪資明細 | E4: 健保公司負擔 | F4: 勞保公司負擔 | G4: 勞退雇主提繳 | H4: 健保個人負擔 | I4: 勞保個人負擔 | J4: 勞退個人自願提繳
A5: 46023 | E5: =SUMIFS(健保!$D$21:$D$140,健保!$A$21:$A$140,$A5,健保!$B$21:$B$140,$B$2) | F5: =SUMIFS(勞保!$D$21:$D$140,勞保!$A$21:$A$140,$A5,勞保!$B$21:$B$140,$B$2) | G5: =SUMIFS(勞退!$C$21:$C$140,勞退!$A$21:$A$140,$A5,勞退!$B$21:$B$140,$B$2) | H5: =SUMIFS(健保!$C$21:$C$140,健保!$A$21:$A$140,$A5,健保!$B$21:$B$140,$B$2) | I5: =SUMIFS(勞保!$C$21:$C$140,勞保!$A$21:$A$140,$A5,勞保!$B$21:$B$140,$B$2) | J5: =SUMIFS(勞退!$D$21:$D$140,勞退!$A$21:$A$140,$A5,勞退!$B$21:$B$140,$B$2)
A6: 46054 | E6: =SUMIFS(健保!$D$21:$D$140,健保!$A$21:$A$140,$A6,健保!$B$21:$B$140,$B$2) | F6: =SUMIFS(勞保!$D$21:$D$140,勞保!$A$21:$A$140,$A6,勞保!$B$21:$B$140,$B$2) | G6: =SUMIFS(勞退!$C$21:$C$140,勞退!$A$21:$A$140,$A6,勞退!$B$21:$B$140,$B$2) | H6: =SUMIFS(健保!$C$21:$C$140,健保!$A$21:$A$140,$A6,健保!$B$21:$B$140,$B$2) | I6: =SUMIFS(勞保!$C$21:$C$140,勞保!$A$21:$A$140,$A6,勞保!$B$21:$B$140,$B$2) | J6: =SUMIFS(勞退!$D$21:$D$140,勞退!$A$21:$A$140,$A6,勞退!$B$21:$B$140,$B$2)
A7: 46082 | E7: =SUMIFS(健保!$D$21:$D$140,健保!$A$21:$A$140,$A7,健保!$B$21:$B$140,$B$2) | F7: =SUMIFS(勞保!$D$21:$D$140,勞保!$A$21:$A$140,$A7,勞保!$B$21:$B$140,$B$2) | G7: =SUMIFS(勞退!$C$21:$C$140,勞退!$A$21:$A$140,$A7,勞退!$B$21:$B$140,$B$2) | H7: =SUMIFS(健保!$C$21:$C$140,健保!$A$21:$A$140,$A7,健保!$B$21:$B$140,$B$2) | I7: =SUMIFS(勞保!$C$21:$C$140,勞保!$A$21:$A$140,$A7,勞保!$B$21:$B$140,$B$2) | J7: =SUMIFS(勞退!$D$21:$D$140,勞退!$A$21:$A$140,$A7,勞退!$B$21:$B$140,$B$2)
A8: 46113 | E8: =SUMIFS(健保!$D$21:$D$140,健保!$A$21:$A$140,$A8,健保!$B$21:$B$140,$B$2) | F8: =SUMIFS(勞保!$D$21:$D$140,勞保!$A$21:$A$140,$A8,勞保!$B$21:$B$140,$B$2) | G8: =SUMIFS(勞退!$C$21:$C$140,勞退!$A$21:$A$140,$A8,勞退!$B$21:$B$140,$B$2) | H8: =SUMIFS(健保!$C$21:$C$140,健保!$A$21:$A$140,$A8,健保!$B$21:$B$140,$B$2) | I8: =SUMIFS(勞保!$C$21:$C$140,勞保!$A$21:$A$140,$A8,勞保!$B$21:$B$140,$B$2) | J8: =SUMIFS(勞退!$D$21:$D$140,勞退!$A$21:$A$140,$A8,勞退!$B$21:$B$140,$B$2)
A9: 46143 | E9: =SUMIFS(健保!$D$21:$D$140,健保!$A$21:$A$140,$A9,健保!$B$21:$B$140,$B$2) | F9: =SUMIFS(勞保!$D$21:$D$140,勞保!$A$21:$A$140,$A9,勞保!$B$21:$B$140,$B$2) | G9: =SUMIFS(勞退!$C$21:$C$140,勞退!$A$21:$A$140,$A9,勞退!$B$21:$B$140,$B$2) | H9: =SUMIFS(健保!$C$21:$C$140,健保!$A$21:$A$140,$A9,健保!$B$21:$B$140,$B$2) | I9: =SUMIFS(勞保!$C$21:$C$140,勞保!$A$21:$A$140,$A9,勞保!$B$21:$B$140,$B$2) | J9: =SUMIFS(勞退!$D$21:$D$140,勞退!$A$21:$A$140,$A9,勞退!$B$21:$B$140,$B$2)
A10: 46174 | E10: =SUMIFS(健保!$D$21:$D$140,健保!$A$21:$A$140,$A10,健保!$B$21:$B$140,$B$2) | F10: =SUMIFS(勞保!$D$21:$D$140,勞保!$A$21:$A$140,$A10,勞保!$B$21:$B$140,$B$2) | G10: =SUMIFS(勞退!$C$21:$C$140,勞退!$A$21:$A$140,$A10,勞退!$B$21:$B$140,$B$2) | H10: =SUMIFS(健保!$C$21:$C$140,健保!$A$21:$A$140,$A10,健保!$B$21:$B$140,$B$2) | I10: =SUMIFS(勞保!$C$21:$C$140,勞保!$A$21:$A$140,$A10,勞保!$B$21:$B$140,$B$2) | J10: =SUMIFS(勞退!$D$21:$D$140,勞退!$A$21:$A$140,$A10,勞退!$B$21:$B$140,$B$2)
A11: 46204 | E11: =SUMIFS(健保!$D$21:$D$140,健保!$A$21:$A$140,$A11,健保!$B$21:$B$140,$B$2) | F11: =SUMIFS(勞保!$D$21:$D$140,勞保!$A$21:$A$140,$A11,勞保!$B$21:$B$140,$B$2) | G11: =SUMIFS(勞退!$C$21:$C$140,勞退!$A$21:$A$140,$A11,勞退!$B$21:$B$140,$B$2) | H11: =SUMIFS(健保!$C$21:$C$140,健保!$A$21:$A$140,$A11,健保!$B$21:$B$140,$B$2) | I11: =SUMIFS(勞保!$C$21:$C$140,勞保!$A$21:$A$140,$A11,勞保!$B$21:$B$140,$B$2) | J11: =SUMIFS(勞退!$D$21:$D$140,勞退!$A$21:$A$140,$A11,勞退!$B$21:$B$140,$B$2)
A12: 46235 | E12: =SUMIFS(健保!$D$21:$D$140,健保!$A$21:$A$140,$A12,健保!$B$21:$B$140,$B$2) | F12: =SUMIFS(勞保!$D$21:$D$140,勞保!$A$21:$A$140,$A12,勞保!$B$21:$B$140,$B$2) | G12: =SUMIFS(勞退!$C$21:$C$140,勞退!$A$21:$A$140,$A12,勞退!$B$21:$B$140,$B$2) | H12: =SUMIFS(健保!$C$21:$C$140,健保!$A$21:$A$140,$A12,健保!$B$21:$B$140,$B$2) | I12: =SUMIFS(勞保!$C$21:$C$140,勞保!$A$21:$A$140,$A12,勞保!$B$21:$B$140,$B$2) | J12: =SUMIFS(勞退!$D$21:$D$140,勞退!$A$21:$A$140,$A12,勞退!$B$21:$B$140,$B$2)
A13: 46266 | E13: =SUMIFS(健保!$D$21:$D$140,健保!$A$21:$A$140,$A13,健保!$B$21:$B$140,$B$2) | F13: =SUMIFS(勞保!$D$21:$D$140,勞保!$A$21:$A$140,$A13,勞保!$B$21:$B$140,$B$2) | G13: =SUMIFS(勞退!$C$21:$C$140,勞退!$A$21:$A$140,$A13,勞退!$B$21:$B$140,$B$2) | H13: =SUMIFS(健保!$C$21:$C$140,健保!$A$21:$A$140,$A13,健保!$B$21:$B$140,$B$2) | I13: =SUMIFS(勞保!$C$21:$C$140,勞保!$A$21:$A$140,$A13,勞保!$B$21:$B$140,$B$2) | J13: =SUMIFS(勞退!$D$21:$D$140,勞退!$A$21:$A$140,$A13,勞退!$B$21:$B$140,$B$2)
A14: 46296 | E14: =SUMIFS(健保!$D$21:$D$140,健保!$A$21:$A$140,$A14,健保!$B$21:$B$140,$B$2) | F14: =SUMIFS(勞保!$D$21:$D$140,勞保!$A$21:$A$140,$A14,勞保!$B$21:$B$140,$B$2) | G14: =SUMIFS(勞退!$C$21:$C$140,勞退!$A$21:$A$140,$A14,勞退!$B$21:$B$140,$B$2) | H14: =SUMIFS(健保!$C$21:$C$140,健保!$A$21:$A$140,$A14,健保!$B$21:$B$140,$B$2) | I14: =SUMIFS(勞保!$C$21:$C$140,勞保!$A$21:$A$140,$A14,勞保!$B$21:$B$140,$B$2) | J14: =SUMIFS(勞退!$D$21:$D$140,勞退!$A$21:$A$140,$A14,勞退!$B$21:$B$140,$B$2)
A15: 46327 | E15: =SUMIFS(健保!$D$21:$D$140,健保!$A$21:$A$140,$A15,健保!$B$21:$B$140,$B$2) | F15: =SUMIFS(勞保!$D$21:$D$140,勞保!$A$21:$A$140,$A15,勞保!$B$21:$B$140,$B$2) | G15: =SUMIFS(勞退!$C$21:$C$140,勞退!$A$21:$A$140,$A15,勞退!$B$21:$B$140,$B$2) | H15: =SUMIFS(健保!$C$21:$C$140,健保!$A$21:$A$140,$A15,健保!$B$21:$B$140,$B$2) | I15: =SUMIFS(勞保!$C$21:$C$140,勞保!$A$21:$A$140,$A15,勞保!$B$21:$B$140,$B$2) | J15: =SUMIFS(勞退!$D$21:$D$140,勞退!$A$21:$A$140,$A15,勞退!$B$21:$B$140,$B$2)
A16: 46357 | E16: =SUMIFS(健保!$D$21:$D$140,健保!$A$21:$A$140,$A16,健保!$B$21:$B$140,$B$2) | F16: =SUMIFS(勞保!$D$21:$D$140,勞保!$A$21:$A$140,$A16,勞保!$B$21:$B$140,$B$2) | G16: =SUMIFS(勞退!$C$21:$C$140,勞退!$A$21:$A$140,$A16,勞退!$B$21:$B$140,$B$2) | H16: =SUMIFS(健保!$C$21:$C$140,健保!$A$21:$A$140,$A16,健保!$B$21:$B$140,$B$2) | I16: =SUMIFS(勞保!$C$21:$C$140,勞保!$A$21:$A$140,$A16,勞保!$B$21:$B$140,$B$2) | J16: =SUMIFS(勞退!$D$21:$D$140,勞退!$A$21:$A$140,$A16,勞退!$B$21:$B$140,$B$2)
A18: 綠色欄位為自動連動；黃色欄位為手動輸入。

Sheet 員工09
A1: 員工個人薪資與保費紀錄
A2: 員工姓名 | B2: ='員工設定'!B12 | D2: 員工代號 | E2: ='員工設定'!A12
A4: 月份 | B4: 薪資匯款日期 | C4: 薪資金額 | D4: 薪資明細 | E4: 健保公司負擔 | F4: 勞保公司負擔 | G4: 勞退雇主提繳 | H4: 健保個人負擔 | I4: 勞保個人負擔 | J4: 勞退個人自願提繳
A5: 46023 | E5: =SUMIFS(健保!$D$21:$D$140,健保!$A$21:$A$140,$A5,健保!$B$21:$B$140,$B$2) | F5: =SUMIFS(勞保!$D$21:$D$140,勞保!$A$21:$A$140,$A5,勞保!$B$21:$B$140,$B$2) | G5: =SUMIFS(勞退!$C$21:$C$140,勞退!$A$21:$A$140,$A5,勞退!$B$21:$B$140,$B$2) | H5: =SUMIFS(健保!$C$21:$C$140,健保!$A$21:$A$140,$A5,健保!$B$21:$B$140,$B$2) | I5: =SUMIFS(勞保!$C$21:$C$140,勞保!$A$21:$A$140,$A5,勞保!$B$21:$B$140,$B$2) | J5: =SUMIFS(勞退!$D$21:$D$140,勞退!$A$21:$A$140,$A5,勞退!$B$21:$B$140,$B$2)
A6: 46054 | E6: =SUMIFS(健保!$D$21:$D$140,健保!$A$21:$A$140,$A6,健保!$B$21:$B$140,$B$2) | F6: =SUMIFS(勞保!$D$21:$D$140,勞保!$A$21:$A$140,$A6,勞保!$B$21:$B$140,$B$2) | G6: =SUMIFS(勞退!$C$21:$C$140,勞退!$A$21:$A$140,$A6,勞退!$B$21:$B$140,$B$2) | H6: =SUMIFS(健保!$C$21:$C$140,健保!$A$21:$A$140,$A6,健保!$B$21:$B$140,$B$2) | I6: =SUMIFS(勞保!$C$21:$C$140,勞保!$A$21:$A$140,$A6,勞保!$B$21:$B$140,$B$2) | J6: =SUMIFS(勞退!$D$21:$D$140,勞退!$A$21:$A$140,$A6,勞退!$B$21:$B$140,$B$2)
A7: 46082 | E7: =SUMIFS(健保!$D$21:$D$140,健保!$A$21:$A$140,$A7,健保!$B$21:$B$140,$B$2) | F7: =SUMIFS(勞保!$D$21:$D$140,勞保!$A$21:$A$140,$A7,勞保!$B$21:$B$140,$B$2) | G7: =SUMIFS(勞退!$C$21:$C$140,勞退!$A$21:$A$140,$A7,勞退!$B$21:$B$140,$B$2) | H7: =SUMIFS(健保!$C$21:$C$140,健保!$A$21:$A$140,$A7,健保!$B$21:$B$140,$B$2) | I7: =SUMIFS(勞保!$C$21:$C$140,勞保!$A$21:$A$140,$A7,勞保!$B$21:$B$140,$B$2) | J7: =SUMIFS(勞退!$D$21:$D$140,勞退!$A$21:$A$140,$A7,勞退!$B$21:$B$140,$B$2)
A8: 46113 | E8: =SUMIFS(健保!$D$21:$D$140,健保!$A$21:$A$140,$A8,健保!$B$21:$B$140,$B$2) | F8: =SUMIFS(勞保!$D$21:$D$140,勞保!$A$21:$A$140,$A8,勞保!$B$21:$B$140,$B$2) | G8: =SUMIFS(勞退!$C$21:$C$140,勞退!$A$21:$A$140,$A8,勞退!$B$21:$B$140,$B$2) | H8: =SUMIFS(健保!$C$21:$C$140,健保!$A$21:$A$140,$A8,健保!$B$21:$B$140,$B$2) | I8: =SUMIFS(勞保!$C$21:$C$140,勞保!$A$21:$A$140,$A8,勞保!$B$21:$B$140,$B$2) | J8: =SUMIFS(勞退!$D$21:$D$140,勞退!$A$21:$A$140,$A8,勞退!$B$21:$B$140,$B$2)
A9: 46143 | E9: =SUMIFS(健保!$D$21:$D$140,健保!$A$21:$A$140,$A9,健保!$B$21:$B$140,$B$2) | F9: =SUMIFS(勞保!$D$21:$D$140,勞保!$A$21:$A$140,$A9,勞保!$B$21:$B$140,$B$2) | G9: =SUMIFS(勞退!$C$21:$C$140,勞退!$A$21:$A$140,$A9,勞退!$B$21:$B$140,$B$2) | H9: =SUMIFS(健保!$C$21:$C$140,健保!$A$21:$A$140,$A9,健保!$B$21:$B$140,$B$2) | I9: =SUMIFS(勞保!$C$21:$C$140,勞保!$A$21:$A$140,$A9,勞保!$B$21:$B$140,$B$2) | J9: =SUMIFS(勞退!$D$21:$D$140,勞退!$A$21:$A$140,$A9,勞退!$B$21:$B$140,$B$2)
A10: 46174 | E10: =SUMIFS(健保!$D$21:$D$140,健保!$A$21:$A$140,$A10,健保!$B$21:$B$140,$B$2) | F10: =SUMIFS(勞保!$D$21:$D$140,勞保!$A$21:$A$140,$A10,勞保!$B$21:$B$140,$B$2) | G10: =SUMIFS(勞退!$C$21:$C$140,勞退!$A$21:$A$140,$A10,勞退!$B$21:$B$140,$B$2) | H10: =SUMIFS(健保!$C$21:$C$140,健保!$A$21:$A$140,$A10,健保!$B$21:$B$140,$B$2) | I10: =SUMIFS(勞保!$C$21:$C$140,勞保!$A$21:$A$140,$A10,勞保!$B$21:$B$140,$B$2) | J10: =SUMIFS(勞退!$D$21:$D$140,勞退!$A$21:$A$140,$A10,勞退!$B$21:$B$140,$B$2)
A11: 46204 | E11: =SUMIFS(健保!$D$21:$D$140,健保!$A$21:$A$140,$A11,健保!$B$21:$B$140,$B$2) | F11: =SUMIFS(勞保!$D$21:$D$140,勞保!$A$21:$A$140,$A11,勞保!$B$21:$B$140,$B$2) | G11: =SUMIFS(勞退!$C$21:$C$140,勞退!$A$21:$A$140,$A11,勞退!$B$21:$B$140,$B$2) | H11: =SUMIFS(健保!$C$21:$C$140,健保!$A$21:$A$140,$A11,健保!$B$21:$B$140,$B$2) | I11: =SUMIFS(勞保!$C$21:$C$140,勞保!$A$21:$A$140,$A11,勞保!$B$21:$B$140,$B$2) | J11: =SUMIFS(勞退!$D$21:$D$140,勞退!$A$21:$A$140,$A11,勞退!$B$21:$B$140,$B$2)
A12: 46235 | E12: =SUMIFS(健保!$D$21:$D$140,健保!$A$21:$A$140,$A12,健保!$B$21:$B$140,$B$2) | F12: =SUMIFS(勞保!$D$21:$D$140,勞保!$A$21:$A$140,$A12,勞保!$B$21:$B$140,$B$2) | G12: =SUMIFS(勞退!$C$21:$C$140,勞退!$A$21:$A$140,$A12,勞退!$B$21:$B$140,$B$2) | H12: =SUMIFS(健保!$C$21:$C$140,健保!$A$21:$A$140,$A12,健保!$B$21:$B$140,$B$2) | I12: =SUMIFS(勞保!$C$21:$C$140,勞保!$A$21:$A$140,$A12,勞保!$B$21:$B$140,$B$2) | J12: =SUMIFS(勞退!$D$21:$D$140,勞退!$A$21:$A$140,$A12,勞退!$B$21:$B$140,$B$2)
A13: 46266 | E13: =SUMIFS(健保!$D$21:$D$140,健保!$A$21:$A$140,$A13,健保!$B$21:$B$140,$B$2) | F13: =SUMIFS(勞保!$D$21:$D$140,勞保!$A$21:$A$140,$A13,勞保!$B$21:$B$140,$B$2) | G13: =SUMIFS(勞退!$C$21:$C$140,勞退!$A$21:$A$140,$A13,勞退!$B$21:$B$140,$B$2) | H13: =SUMIFS(健保!$C$21:$C$140,健保!$A$21:$A$140,$A13,健保!$B$21:$B$140,$B$2) | I13: =SUMIFS(勞保!$C$21:$C$140,勞保!$A$21:$A$140,$A13,勞保!$B$21:$B$140,$B$2) | J13: =SUMIFS(勞退!$D$21:$D$140,勞退!$A$21:$A$140,$A13,勞退!$B$21:$B$140,$B$2)
A14: 46296 | E14: =SUMIFS(健保!$D$21:$D$140,健保!$A$21:$A$140,$A14,健保!$B$21:$B$140,$B$2) | F14: =SUMIFS(勞保!$D$21:$D$140,勞保!$A$21:$A$140,$A14,勞保!$B$21:$B$140,$B$2) | G14: =SUMIFS(勞退!$C$21:$C$140,勞退!$A$21:$A$140,$A14,勞退!$B$21:$B$140,$B$2) | H14: =SUMIFS(健保!$C$21:$C$140,健保!$A$21:$A$140,$A14,健保!$B$21:$B$140,$B$2) | I14: =SUMIFS(勞保!$C$21:$C$140,勞保!$A$21:$A$140,$A14,勞保!$B$21:$B$140,$B$2) | J14: =SUMIFS(勞退!$D$21:$D$140,勞退!$A$21:$A$140,$A14,勞退!$B$21:$B$140,$B$2)
A15: 46327 | E15: =SUMIFS(健保!$D$21:$D$140,健保!$A$21:$A$140,$A15,健保!$B$21:$B$140,$B$2) | F15: =SUMIFS(勞保!$D$21:$D$140,勞保!$A$21:$A$140,$A15,勞保!$B$21:$B$140,$B$2) | G15: =SUMIFS(勞退!$C$21:$C$140,勞退!$A$21:$A$140,$A15,勞退!$B$21:$B$140,$B$2) | H15: =SUMIFS(健保!$C$21:$C$140,健保!$A$21:$A$140,$A15,健保!$B$21:$B$140,$B$2) | I15: =SUMIFS(勞保!$C$21:$C$140,勞保!$A$21:$A$140,$A15,勞保!$B$21:$B$140,$B$2) | J15: =SUMIFS(勞退!$D$21:$D$140,勞退!$A$21:$A$140,$A15,勞退!$B$21:$B$140,$B$2)
A16: 46357 | E16: =SUMIFS(健保!$D$21:$D$140,健保!$A$21:$A$140,$A16,健保!$B$21:$B$140,$B$2) | F16: =SUMIFS(勞保!$D$21:$D$140,勞保!$A$21:$A$140,$A16,勞保!$B$21:$B$140,$B$2) | G16: =SUMIFS(勞退!$C$21:$C$140,勞退!$A$21:$A$140,$A16,勞退!$B$21:$B$140,$B$2) | H16: =SUMIFS(健保!$C$21:$C$140,健保!$A$21:$A$140,$A16,健保!$B$21:$B$140,$B$2) | I16: =SUMIFS(勞保!$C$21:$C$140,勞保!$A$21:$A$140,$A16,勞保!$B$21:$B$140,$B$2) | J16: =SUMIFS(勞退!$D$21:$D$140,勞退!$A$21:$A$140,$A16,勞退!$B$21:$B$140,$B$2)
A18: 綠色欄位為自動連動；黃色欄位為手動輸入。

Sheet 員工10
A1: 員工個人薪資與保費紀錄
A2: 員工姓名 | B2: ='員工設定'!B13 | D2: 員工代號 | E2: ='員工設定'!A13
A4: 月份 | B4: 薪資匯款日期 | C4: 薪資金額 | D4: 薪資明細 | E4: 健保公司負擔 | F4: 勞保公司負擔 | G4: 勞退雇主提繳 | H4: 健保個人負擔 | I4: 勞保個人負擔 | J4: 勞退個人自願提繳
A5: 46023 | E5: =SUMIFS(健保!$D$21:$D$140,健保!$A$21:$A$140,$A5,健保!$B$21:$B$140,$B$2) | F5: =SUMIFS(勞保!$D$21:$D$140,勞保!$A$21:$A$140,$A5,勞保!$B$21:$B$140,$B$2) | G5: =SUMIFS(勞退!$C$21:$C$140,勞退!$A$21:$A$140,$A5,勞退!$B$21:$B$140,$B$2) | H5: =SUMIFS(健保!$C$21:$C$140,健保!$A$21:$A$140,$A5,健保!$B$21:$B$140,$B$2) | I5: =SUMIFS(勞保!$C$21:$C$140,勞保!$A$21:$A$140,$A5,勞保!$B$21:$B$140,$B$2) | J5: =SUMIFS(勞退!$D$21:$D$140,勞退!$A$21:$A$140,$A5,勞退!$B$21:$B$140,$B$2)
A6: 46054 | E6: =SUMIFS(健保!$D$21:$D$140,健保!$A$21:$A$140,$A6,健保!$B$21:$B$140,$B$2) | F6: =SUMIFS(勞保!$D$21:$D$140,勞保!$A$21:$A$140,$A6,勞保!$B$21:$B$140,$B$2) | G6: =SUMIFS(勞退!$C$21:$C$140,勞退!$A$21:$A$140,$A6,勞退!$B$21:$B$140,$B$2) | H6: =SUMIFS(健保!$C$21:$C$140,健保!$A$21:$A$140,$A6,健保!$B$21:$B$140,$B$2) | I6: =SUMIFS(勞保!$C$21:$C$140,勞保!$A$21:$A$140,$A6,勞保!$B$21:$B$140,$B$2) | J6: =SUMIFS(勞退!$D$21:$D$140,勞退!$A$21:$A$140,$A6,勞退!$B$21:$B$140,$B$2)
A7: 46082 | E7: =SUMIFS(健保!$D$21:$D$140,健保!$A$21:$A$140,$A7,健保!$B$21:$B$140,$B$2) | F7: =SUMIFS(勞保!$D$21:$D$140,勞保!$A$21:$A$140,$A7,勞保!$B$21:$B$140,$B$2) | G7: =SUMIFS(勞退!$C$21:$C$140,勞退!$A$21:$A$140,$A7,勞退!$B$21:$B$140,$B$2) | H7: =SUMIFS(健保!$C$21:$C$140,健保!$A$21:$A$140,$A7,健保!$B$21:$B$140,$B$2) | I7: =SUMIFS(勞保!$C$21:$C$140,勞保!$A$21:$A$140,$A7,勞保!$B$21:$B$140,$B$2) | J7: =SUMIFS(勞退!$D$21:$D$140,勞退!$A$21:$A$140,$A7,勞退!$B$21:$B$140,$B$2)
A8: 46113 | E8: =SUMIFS(健保!$D$21:$D$140,健保!$A$21:$A$140,$A8,健保!$B$21:$B$140,$B$2) | F8: =SUMIFS(勞保!$D$21:$D$140,勞保!$A$21:$A$140,$A8,勞保!$B$21:$B$140,$B$2) | G8: =SUMIFS(勞退!$C$21:$C$140,勞退!$A$21:$A$140,$A8,勞退!$B$21:$B$140,$B$2) | H8: =SUMIFS(健保!$C$21:$C$140,健保!$A$21:$A$140,$A8,健保!$B$21:$B$140,$B$2) | I8: =SUMIFS(勞保!$C$21:$C$140,勞保!$A$21:$A$140,$A8,勞保!$B$21:$B$140,$B$2) | J8: =SUMIFS(勞退!$D$21:$D$140,勞退!$A$21:$A$140,$A8,勞退!$B$21:$B$140,$B$2)
A9: 46143 | E9: =SUMIFS(健保!$D$21:$D$140,健保!$A$21:$A$140,$A9,健保!$B$21:$B$140,$B$2) | F9: =SUMIFS(勞保!$D$21:$D$140,勞保!$A$21:$A$140,$A9,勞保!$B$21:$B$140,$B$2) | G9: =SUMIFS(勞退!$C$21:$C$140,勞退!$A$21:$A$140,$A9,勞退!$B$21:$B$140,$B$2) | H9: =SUMIFS(健保!$C$21:$C$140,健保!$A$21:$A$140,$A9,健保!$B$21:$B$140,$B$2) | I9: =SUMIFS(勞保!$C$21:$C$140,勞保!$A$21:$A$140,$A9,勞保!$B$21:$B$140,$B$2) | J9: =SUMIFS(勞退!$D$21:$D$140,勞退!$A$21:$A$140,$A9,勞退!$B$21:$B$140,$B$2)
A10: 46174 | E10: =SUMIFS(健保!$D$21:$D$140,健保!$A$21:$A$140,$A10,健保!$B$21:$B$140,$B$2) | F10: =SUMIFS(勞保!$D$21:$D$140,勞保!$A$21:$A$140,$A10,勞保!$B$21:$B$140,$B$2) | G10: =SUMIFS(勞退!$C$21:$C$140,勞退!$A$21:$A$140,$A10,勞退!$B$21:$B$140,$B$2) | H10: =SUMIFS(健保!$C$21:$C$140,健保!$A$21:$A$140,$A10,健保!$B$21:$B$140,$B$2) | I10: =SUMIFS(勞保!$C$21:$C$140,勞保!$A$21:$A$140,$A10,勞保!$B$21:$B$140,$B$2) | J10: =SUMIFS(勞退!$D$21:$D$140,勞退!$A$21:$A$140,$A10,勞退!$B$21:$B$140,$B$2)
A11: 46204 | E11: =SUMIFS(健保!$D$21:$D$140,健保!$A$21:$A$140,$A11,健保!$B$21:$B$140,$B$2) | F11: =SUMIFS(勞保!$D$21:$D$140,勞保!$A$21:$A$140,$A11,勞保!$B$21:$B$140,$B$2) | G11: =SUMIFS(勞退!$C$21:$C$140,勞退!$A$21:$A$140,$A11,勞退!$B$21:$B$140,$B$2) | H11: =SUMIFS(健保!$C$21:$C$140,健保!$A$21:$A$140,$A11,健保!$B$21:$B$140,$B$2) | I11: =SUMIFS(勞保!$C$21:$C$140,勞保!$A$21:$A$140,$A11,勞保!$B$21:$B$140,$B$2) | J11: =SUMIFS(勞退!$D$21:$D$140,勞退!$A$21:$A$140,$A11,勞退!$B$21:$B$140,$B$2)
A12: 46235 | E12: =SUMIFS(健保!$D$21:$D$140,健保!$A$21:$A$140,$A12,健保!$B$21:$B$140,$B$2) | F12: =SUMIFS(勞保!$D$21:$D$140,勞保!$A$21:$A$140,$A12,勞保!$B$21:$B$140,$B$2) | G12: =SUMIFS(勞退!$C$21:$C$140,勞退!$A$21:$A$140,$A12,勞退!$B$21:$B$140,$B$2) | H12: =SUMIFS(健保!$C$21:$C$140,健保!$A$21:$A$140,$A12,健保!$B$21:$B$140,$B$2) | I12: =SUMIFS(勞保!$C$21:$C$140,勞保!$A$21:$A$140,$A12,勞保!$B$21:$B$140,$B$2) | J12: =SUMIFS(勞退!$D$21:$D$140,勞退!$A$21:$A$140,$A12,勞退!$B$21:$B$140,$B$2)
A13: 46266 | E13: =SUMIFS(健保!$D$21:$D$140,健保!$A$21:$A$140,$A13,健保!$B$21:$B$140,$B$2) | F13: =SUMIFS(勞保!$D$21:$D$140,勞保!$A$21:$A$140,$A13,勞保!$B$21:$B$140,$B$2) | G13: =SUMIFS(勞退!$C$21:$C$140,勞退!$A$21:$A$140,$A13,勞退!$B$21:$B$140,$B$2) | H13: =SUMIFS(健保!$C$21:$C$140,健保!$A$21:$A$140,$A13,健保!$B$21:$B$140,$B$2) | I13: =SUMIFS(勞保!$C$21:$C$140,勞保!$A$21:$A$140,$A13,勞保!$B$21:$B$140,$B$2) | J13: =SUMIFS(勞退!$D$21:$D$140,勞退!$A$21:$A$140,$A13,勞退!$B$21:$B$140,$B$2)
A14: 46296 | E14: =SUMIFS(健保!$D$21:$D$140,健保!$A$21:$A$140,$A14,健保!$B$21:$B$140,$B$2) | F14: =SUMIFS(勞保!$D$21:$D$140,勞保!$A$21:$A$140,$A14,勞保!$B$21:$B$140,$B$2) | G14: =SUMIFS(勞退!$C$21:$C$140,勞退!$A$21:$A$140,$A14,勞退!$B$21:$B$140,$B$2) | H14: =SUMIFS(健保!$C$21:$C$140,健保!$A$21:$A$140,$A14,健保!$B$21:$B$140,$B$2) | I14: =SUMIFS(勞保!$C$21:$C$140,勞保!$A$21:$A$140,$A14,勞保!$B$21:$B$140,$B$2) | J14: =SUMIFS(勞退!$D$21:$D$140,勞退!$A$21:$A$140,$A14,勞退!$B$21:$B$140,$B$2)
